Workbook
Name Daily__Online_Reservation: '1.b Model_Best estimates'!$H$4
Name Daily_Miscellaneous_expenses: '1.b Model_Best estimates'!$H$7
Name Late_Cancellation: '1.b Model_Best estimates'!$H$5
Name Number_of_Walkins: '1.b Model_Best estimates'!$H$6
Name Total_Daily_Profit: '1.b Model_Best estimates'!$C$10

Sheet 1.a Manager's Page
B3: Stochastic inputs | C3: Desription and assumption
B4: Daily Online Reservation | C4: Description: This tracks how many bookings we get online each day, which really drives our occupancy. Assumption: We used a Poisson distribution with an average of 25 bookings, since they come in one by one and there’s no limit during peak season.
B5: Late Cancellation | C5: Description: This is the number of bookings that get canceled last minute, affecting how many rooms we have free. Assumption: We used a Poisson distribution with an average of about 3 cancellations, since they’re random. Also, we charge higher fees ($40 or $80) in peak season to discourage cancellations when we’re super busy.
B6: Number of Walkins | C6: Description: These are the guests who show up without booking ahead, which can really help fill rooms. Assumption: We based this on past data, using an Empirical distribution for 0 to 5 walk-ins, and we’ll take them as long as we’re within our overbooking limit.
B7: Daily Miscellaneous expenses | C7: Description: These are the random daily costs we can’t predict exactly, like extra supplies or utilities. Assumption: We went with a Uniform distribution between $0 and $600, since these costs can vary a lot but are equally likely within that range.
B9: Decision variables | C9: Desription and assumption
B10: Room Rate | C10: Description: This is what we charge per room each night, which affects how much we earn and how many people book. These are the 4 assumption we consider for the room rate and late cancellation as the management want consider these price points for the Motel Roomrate and late cancellation. : Assumption 1 : Room rate $ 240 and late cancel fee $40 Rationale:Keeps our price point attractive to stimulate demand when guest traffic is light. A small $40 fee nudges guests to honor reservations without pushing them away. Assumption 2 Option 2: Room rate $ 240 and late cancel fee $80 Rationale :Maintains an accessible $240 rate to capture mid-season travellers. The $80 penalty helps offset revenue lost to last-minute cancellations when demand isn’t urgent. Assumption 3 : when Room rate $ 280 and late cancel fee $40 Rationale: Signals a boutique upgrade at $280 to raise average spend while the lighter $40 fee preserves goodwill for guests who might rethink during a still-flexible period. Assumption 4 : Room rate $ 280 and late cancel fee $80 Rationale : Maximizes per-night revenue at $280 and strongly deters no-shows with an $80 fee—critical for protecting income when every room is at a premium. Management will choose one of these rates as the daily price strategy to Optimize the profit and Room Occupency.
B11: Late Cancellation Fees | C11: Description: This is the fee we charge if someone cancels late, helping us cover the lost booking. Assumption: We have two fees, $40 and $80, and we bump it up to $80 during peak season since rooms are in high demand and we can enforce stricter penalties.
B13: Fixed inputs | C13: Desription and assumption
B14: Number of Rooms | C14: Description: This is the total number of rooms we have at Coastal Nest Motel, so we know how many guests we can take in. Assumption: We’re working with 50 rooms, which feels right for a cozy boutique motel like ours.
B15: Housing keeping Cost per day | C15: Description: This is what we pay to clean each room every day once it’s been used, keeping things nice and tidy for guests. Assumption: We set it at $30 per room, which is pretty standard for the industry, and we’re not counting extra cleaning costs for now.
B16: Fixed Staff Salary | C16: Description: This is the daily pay for our permanent staff, like a fixed cost we know we’ll have no matter what. Assumption: It’s $3,800 a day, and we’re not including any extra staff costs for now.
... B24: Total Operation Cost | C24: Description: This is what we spend daily to keep the motel running, both fixed and variable costs. Assumption: We add up housekeeping ($30 per occupied room), miscellaneous expenses, staff salary ($3,800), and admin overhead ($200)
B26: OUTPUT
B27: Total Daily Profit | C27: Description: This is what we’re left with after paying all our costs, showing how much we actually make each day. Assumption: We get this by subtracting our total operation cost from our sales revenue, assuming demand stays steady during peak season.
B28: Sold Out: Yes/ No | C28: Description: This tells us if we’ve filled all 50 rooms or not, so we know if we’re at capacity. Assumption: We mark it as “Yes” if we hit or go over 50 rooms, considering our overbooking allowance.

Sheet 1.b Model_Best estimates
B1: MODEL BEST GUESS
G2: INPUTS
B3: CALCULATED VALUES & OUTPUT | C3: values | G3: Stochastic inputs | H3: values | I3: Type of Distribution
B4: Number of Occupied rooms | C4: =ROUNDDOWN(MIN(H4+H6-H5),H18*(1+H21)) -> 39 | G4: Daily Online Reservation | H4: 36 | I4: Poisson Distribution
B5: Total Sales Revenue | C5: =C4*H12+H5*H13 -> 9440 | G5: Late Cancellation | H5: 2 | I5: Poisson Distribution
B6: Total Operation Cost | C6: =C4*H19+H7+H20+H22 -> 5696 | G6: Number of Walkins | H6: 5 | I6: Empirical Distribution
G7: Daily Miscellaneous expenses | H7: 526 | I7: Uniform Distribution
B9: OUTPUT | C9: values
B10: Total Daily Profit | C10: =C5-C6 -> 3744
B11: Sold Out: Yes/ No | C11: =IF(C4=H18,"Yes","No") -> No | G11: Decision variables | H11: values
G12: Room Rate | H12: 240
G13: Late Cancellation Fees | H13: 40
G17: Fixed inputs | H17: values
G18: Number of Rooms | H18: 50
G19: Housing keeping Cost per day | H19: 30
G20: Fixed Staff Salary | H20: 3800
G21: Over Booking rate | H21: 0.05
G22: Front Desk and Administration Overhead per day | H22: 200

Sheet 1.c Model Simulated data
B1: MODEL SIMULATION
G2: INPUTS
B3: CALCULATED VALUES & OUTPUT | C3: values | G3: Stochastic inputs | H3: values | I3: Type of Distribution
B4: Number of Occupied rooms | C4: =ROUNDDOWN(MIN(H4+H6-H5),H18*(1+H21)) -> 18 | G4: Daily Online Reservation | H4: =VLOOKUP(RAND(),'3.Probability Distributions '!D5:F56,3,TRUE) -> 21 | I4: Poisson Distribution
B5: Total Sales Revenue | C5: =C4*H12+H5*H13 -> 4560 | G5: Late Cancellation | H5: =VLOOKUP(RAND(),'3.Probability Distributions '!M5:O16,3,TRUE) -> 6 | I5: Poisson Distribution
B6: Total Operation Cost | C6: =C4*H19+H7+H20+H22 -> 4834.8733 | G6: Number of Walkins | H6: =VLOOKUP(RAND(),'3.Probability Distributions '!X5:Z11,3,TRUE) -> 3 | I6: Empirical Distribution
G7: Daily Miscellaneous expenses | H7: ='3.Probability Distributions '!AE6+('3.Probability Distributions '!AF6-'3.Probability Distributions '!AE6)*RAND() -> 294.87332 | I7: Uniform Distribution
B9: OUTPUT | C9: values
B10: Total Daily Profit | C10: =C5-C6 -> -274.87332
B11: Sold Out: Yes/ No | C11: =IF(C4=H18,"Yes","No") -> No | G11: Decision variables | H11: values
G12: Room Rate | H12: 240
G13: Late Cancellation Fees | H13: 40
G17: Fixed inputs | H17: values
G18: Number of Rooms | H18: 50
G19: Housing keeping Cost per day | H19: 30
G20: Fixed Staff Salary Per day | H20: 3800
G21: Over Booking rate | H21: 0.05
G22: Front Desk and Administration Overhead per day | H22: 200

Sheet 2.a.1 Scenario for $240 and $40
A1: 1. Scenario Analysis For Daily Online Reservation ($240 and $40)
J2: Summary of FIndings:Under the $240/$40 policy, a full house of 50 online bookings (Best case) lifts daily profit from Current $3,744 to $6,054. In the Base case of 25 reservations, profit contracts to $1,434, and if no one books online (Worst case), the motel incurs a –$3,816 loss. These figures clearly demonstrate that online demand is the single most important lever: each additional reservation adds directly to revenue, while empty rooms leave fixed and variable costs uncovered.
B3: Scenario Summary
D4: Current Values: | E4: Best Case | F4: Base Case | G4: Worst Case
B6: Changing Cells:
C7: Daily__Online_Reservation | D7: 36 | E7: 50 | F7: 25 | G7: 0
B8: Result Cells:
C9: Total_Daily_Profit | D9: 3744 | E9: 6054 | F9: 1434 | G9: -3816
B10: Notes: Current Values column represents values of changing cells at
B11: time Scenario Summary Report was created. Changing cells for each
B12: scenario are highlighted in gray.
A15: 2. Scenario Analysis For Late Cancellation ($240 and $40)
B17: Scenario Summary | J17: Summary of FIndings: Eliminating late cancellations entirely (Best case) increases profit from $3,744 to $4,084. At the Base case of three cancellations, profit stands at $3,574, and if cancellations climb to six (Worst case), profit falls to $3,064. Every prevented cancellation preserves roughly $170 in daily revenue—underscoring that modest investments in reminder communications or a stricter cancellation policy can produce a meaningful uplift in profitability.
D18: Current Values: | E18: Best Case | F18: Base Case | G18: Worst Case
B20: Changing Cells:
C21: Late_Cancellation | D21: 2 | E21: 0 | F21: 3 | G21: 6
B22: Result Cells:
C23: Total_Daily_Profit | D23: 3744 | E23: 4084 | F23: 3574 | G23: 3064
B24: Notes: Current Values column represents values of changing cells at
B25: time Scenario Summary Report was created. Changing cells for each
B26: scenario are highlighted in gray.
A29: 3. Scenario Analysis For Number of walkins ($240 and $40)
B31: Scenario Summary | J31: Summary of FIndings: When five spontaneous walk-in guests fill any open rooms (Best case), profit remains at the current level of $3,744, reflecting full capacity utilization. With three walk-ins (Base case), profit declines to $3,324, and in the absence of any walk-ins (Worst case), profit drops to $2,634. These results highlight that each additional walk-in contributes approximately $420 in net daily profit, making targeted local marketing or clear “Vacancy” signage a high-impact strategy.
D32: Current Values: | E32: Best Case | F32: Base Case | G32: Worst Case
B34: Changing Cells:
C35: Number_of_Walkins | D35: 5 | E35: 5 | F35: 3 | G35: 0
B36: Result Cells:
C37: Total_Daily_Profit | D37: 3744 | E37: 3744 | F37: 3324 | G37: 2694
B38: Notes: Current Values column represents values of changing cells at
B39: time Scenario Summary Report was created. Changing cells for each
B40: scenario are highlighted in gray.
A43: 4. Scenario Analysis For Daily Miscellaneous expenses ($240 and $40)
J44: Summary of FIndings : Reducing miscellaneous expenses to zero (Best case) boosts profit from $3,744 to $4,270. At a mid-range cost of $300 (Base case), profit is $3,740, and even under the Worst case of $600 in expenses, profit remains positive at $3,670. Although these cost variances have a smaller effect than occupancy changes, every dollar saved on day-to-day expenses flows straight to the bottom line—so disciplined vendor negotiations and expense oversight will support steadier margins.
B45: Scenario Summary
D46: Current Values: | E46: Best Case | F46: Base Case | G46: Worst Case
B48: Changing Cells:
C49: Daily_Miscellaneous_expenses | D49: 526 | E49: 0 | F49: 300 | G49: 600
B50: Result Cells:
C51: Total_Daily_Profit | D51: 3744 | E51: 4270 | F51: 3970 | G51: 3670
B52: Notes: Current Values column represents values of changing cells at
...

Sheet 2.a.2 Scenario for $240 and $80
A1: 1. Scenario Analysis For Daily Online Reservation ($240 and $80)
B3: Scenario Summary | J3: Summary of Findings: Under the $240/$80 pricing policy, filling all 50 rooms with online bookings (Best case) lifts daily profit from the current $3,824 to $6,134. At the Base case of 25 reservations, profit falls sharply to $1,514, while in the Worst case of zero bookings the motel faces a –$3,736 loss. These results reaffirm that online demand drives profitability: every additional booking directly contributes room-rate revenue (net of cleaning costs), whereas empty rooms leave fixed and variable expenses uncovered.
D4: Current Values: | E4: Best Case | F4: Base Case | G4: Worst Case
B6: Changing Cells:
C7: Daily__Online_Reservation | D7: 36 | E7: 50 | F7: 25 | G7: 0
B8: Result Cells:
C9: Total_Daily_Profit | D9: 3824 | E9: 6134 | F9: 1514 | G9: -3736
B10: Notes: Current Values column represents values of changing cells at
B11: time Scenario Summary Report was created. Changing cells for each
B12: scenario are highlighted in gray.
A15: 2. Scenario Analysis For Late Cancellation ($240 and $80)
J16: Summary of Findings:Eliminating late cancellations altogether (Best case) increases profit from $3,824 to $4,084. Under the Base case of three cancellations, profit sits at $3,634, and if cancellations rise to six (Worst case), profit declines to $3,304. Each avoided cancellation thus preserves roughly $160 of daily revenue, demonstrating that simple measures—such as tighter policy terms or targeted reminders—can meaningfully bolster the bottom line.
B17: Scenario Summary
D18: Current Values: | E18: Best Case | F18: Base Case | G18: Worst Case
B20: Changing Cells:
C21: Late_Cancellation | D21: 2 | E21: 0 | F21: 3 | G21: 6
B22: Result Cells:
C23: Total_Daily_Profit | D23: 3824 | E23: 4084 | F23: 3694 | G23: 3304
B24: Notes: Current Values column represents values of changing cells at
B25: time Scenario Summary Report was created. Changing cells for each
B26: scenario are highlighted in gray.
A29: 3. Scenario Analysis For Number of Walkins ($240 and $80) | J29: Summary of Findings: When five spontaneous walk-in guests occupy remaining rooms (Best case), profit remains at the current level of $3,824, reflecting full capacity. If walk-ins drop to three (Base case), profit decreases to $3,404, and with no walk-ins (Worst case) profit falls further to $2,774. This highlights that each additional walk-in guest contributes approximately $420 in net profit, making last-minute promotions or visible vacancy signage an effective strategy to capture incremental demand.
B31: Scenario Summary
D32: Current Values: | E32: Best Case | F32: Base Case | G32: Worst Case
B34: Changing Cells:
C35: Number_of_Walkins | D35: 5 | E35: 5 | F35: 3 | G35: 0
B36: Result Cells:
C37: Total_Daily_Profit | D37: 3824 | E37: 3824 | F37: 3404 | G37: 2774
B38: Notes: Current Values column represents values of changing cells at
B39: time Scenario Summary Report was created. Changing cells for each
B40: scenario are highlighted in gray.
A42: 4. Scenario Analysis For Daily Miscellaneous expenses ($240 and $80)
J43: Summary of Findings: Reducing daily miscellaneous expenses to zero (Best case) boosts profit to $4,350. At a mid-range expense of $300 (Base case), profit is $4,050, and even under the Worst case of $600 in expenses, the motel still earns $3,750. While cost-control swings are less dramatic than occupancy effects, every dollar saved flows directly to the bottom line—underscoring the value of disciplined procurement and expense oversight in supporting overall profitability.
B44: Scenario Summary
D45: Current Values: | E45: Best Case | F45: Base Case | G45: Worst Case
B47: Changing Cells:
C48: Daily_Miscellaneous_expenses | D48: 526 | E48: 0 | F48: 300 | G48: 600
B49: Result Cells:
C50: Total_Daily_Profit | D50: 3824 | E50: 4350 | F50: 4050 | G50: 3750
B51: Notes: Current Values column represents values of changing cells at
...

Sheet 2.a.3 Scenario for $280 and $40
A1: 1. Scenario Analysis For Daily Online Reservation ($280 and $40)
J2: Summary of Findings: Under the best‐case scenario of 50 online bookings, daily profit increases from the current $5,304 to $8,054. In a base‐case environment of 25 reservations, profit declines to $2,554. If no reservations are received, the motel incurs a loss of $3,636. These results underscore that reservation volume is the primary driver of financial performance: each additional booking contributes directly to revenue, while empty rooms rapidly erode both fixed and variable cost coverage.
B3: Scenario Summary
D4: Current Values: | E4: Best Case | F4: Base Case | G4: Worst Case
B6: Changing Cells:
C7: Daily__Online_Reservation | D7: 36 | E7: 50 | F7: 25 | G7: 0
B8: Result Cells:
C9: Total_Daily_Profit | D9: 5304 | E9: 8054 | F9: 2554 | G9: -3696
B10: Notes: Current Values column represents values of changing cells at
B11: time Scenario Summary Report was created. Changing cells for each
B12: scenario are highlighted in gray.
A15: 2. Scenario Analysis For Late Cancellation ($280 and $40)
B17: Scenario Summary | J17: Summary of Findings: When late cancellations are eliminated entirely, profit rises to $5,724—an improvement of $420 over Current $5,304. Under the base‐case of three cancellations, profit settles at $5,094, and even in a worst‐case scenario of six cancellations, the motel still generates $4,464. Every prevented cancellation preserves approximately $170 in daily revenue, indicating that modest investments in cancellation‐reduction measures (such as reminder communications or nominal retention incentives) can yield appreciable bottom-line benefits.
D18: Current Values: | E18: Best Case | F18: Base Case | G18: Worst Case
B20: Changing Cells:
C21: Late_Cancellation | D21: 2 | E21: 0 | F21: 3 | G21: 6
B22: Result Cells:
C23: Total_Daily_Profit | D23: 5304 | E23: 5724 | F23: 5094 | G23: 4464
B24: Notes: Current Values column represents values of changing cells at
B25: time Scenario Summary Report was created. Changing cells for each
B26: scenario are highlighted in gray.
A28: 3. Scenario Analysis For Number of Walkins ($280 and $40) | J28: Summary of Findings:In the best case—with five unanticipated walk-in guests filling any remaining capacity—the motel achieves its current profit level of $5,304. Should walk-in traffic decline to three guests, profit falls to $4,804, and with zero walk-ins, profit further decreases to $4,054. These findings highlight the value of capturing spontaneous demand: each additional walk-in contributes roughly $500 in net profit. Targeted local marketing or enhanced on-site signage can therefore be effective levers for improving occupancy and profitability.
B30: Scenario Summary
D31: Current Values: | E31: Best Case | F31: Base Case | G31: Worst Case
B33: Changing Cells:
C34: Number_of_Walkins | D34: 5 | E34: 5 | F34: 3 | G34: 0
B35: Result Cells:
C36: Total_Daily_Profit | D36: 5304 | E36: 5304 | F36: 4804 | G36: 4054
B37: Notes: Current Values column represents values of changing cells at
B38: time Scenario Summary Report was created. Changing cells for each
B39: scenario are highlighted in gray.
A42: 4. Scenario Analysis For Daily Miscellaneous expenses ($280 and $40)
B45: Scenario Summary | J45: Summary of Findings:Reducing daily miscellaneous expenses to zero drives profit up to $5,830. At a mid-range cost of $300, profit measures $5,010, and even under the worst-case expense level of $600, the motel maintains a positive profit of $4,704. Although these expense variances produce smaller swings than changes in occupancy, every dollar saved in variable costs flows immediately to the bottom line. Focused cost-control initiatives—such as negotiated supplier rates and rigorous expense oversight—will therefore support more consistent and resilient profitability.
D46: Current Values: | E46: Best Case | F46: Base Case | G46: Worst Case
B48: Changing Cells:
C49: Daily_Miscellaneous_expenses | D49: 526 | E49: 0 | F49: 300 | G49: 600
B50: Result Cells:
C51: Total_Daily_Profit | D51: 5304 | E51: 5830 | F51: 5530 | G51: 5230
B52: Notes: Current Values column represents values of changing cells at
B53: time Scenario Summary Report was created. Changing cells for each
...

Sheet 2.a.4 Scenario for $280 and $80
B1: 1. Scenario Analysis For Daily Online Reservation ($280 and $80)
C3: Scenario Summary | J3: Summary of Findings: When demand peaks at 50 online bookings (Best case), the motel’s daily profit increase to $8,134. Under a more typical day of 25 reservations (Base case), profit pulls back to $2,634. If, worst-case, no one books online, the motel actually loses $3,616—fixed costs bite hard when rooms sit empty. This tells us that filling rooms is absolutely critical: every extra booking drives significant revenue, while empty rooms quickly turn profitable days into losses.
E4: Current Values: | F4: Best Case | G4: Base Case | H4: Worst Case
C6: Changing Cells:
D7: Daily__Online_Reservation | E7: 36 | F7: 50 | G7: 25 | H7: 0
C8: Result Cells:
D9: Total_Daily_Profit | E9: 5384 | F9: 8134 | G9: 2634 | H9: -3616
C10: Notes: Current Values column represents values of changing cells at
C11: time Scenario Summary Report was created. Changing cells for each
C12: scenario are highlighted in gray.
B15: 2. Scenario Analysis For Late Cancellation ($280 and $80)
C17: Scenario Summary | J17: Summary of Findings: Eliminating late cancellations entirely (Best case) boosts profit to $5,724—about $340 more than today’s $5,384. At three cancellations per day (Base case), profit settles at $5,214. If cancellations climb to six (Worst case), profit falls to $4,704. In other words, each guest who doesn’t cancel late protects roughly $170 of daily revenue—so tightening cancellation policies or offering small incentives to keep bookings makes a noticeable difference.
E18: Current Values: | F18: Best Case | G18: Base Case | H18: Worst Case
C20: Changing Cells:
D21: Late_Cancellation | E21: 2 | F21: 0 | G21: 3 | H21: 6
C22: Result Cells:
D23: Total_Daily_Profit | E23: 5384 | F23: 5724 | G23: 5214 | H23: 4704
C24: Notes: Current Values column represents values of changing cells at
C25: time Scenario Summary Report was created. Changing cells for each
C26: scenario are highlighted in gray.
B28: 3. Scenario Analysis For Number of Walkins ($280 and $80)
C30: Scenario Summary | J30: Summary of Findings: On days when five walk-ins fill any unsold rooms (Best case), profit matches the current $5,384, since capacity is maxed out. If only three walk-ins arrive (Base case), profit dips to $4,884. And with zero walk-ins (Worst case), profit slides further to $4,134. Capturing even a handful of spontaneous guests adds around $500 of net profit each—making local marketing and clear signage a simple, high-impact lever.
E31: Current Values: | F31: Best Case | G31: Base Case | H31: Worst Case
C33: Changing Cells:
D34: Number_of_Walkins | E34: 5 | F34: 5 | G34: 3 | H34: 0
C35: Result Cells:
D36: Total_Daily_Profit | E36: 5384 | F36: 5384 | G36: 4884 | H36: 4134
C37: Notes: Current Values column represents values of changing cells at
C38: time Scenario Summary Report was created. Changing cells for each
C39: scenario are highlighted in gray.
B42: 4. Scenario Analysis For Daily Miscellaneous expenses ($280 and $80)
C45: Scenario Summary | J45: Summary of Findings: When variable costs drop to zero (Best case), profit climbs to $5,910. At a mid-range $300 of expenses (Base case), profit is $5,610. If daily expenses swell to $600 (Worst case), profit still holds a positive $5,310. While expense swings are less dramatic than booking volume, every dollar saved goes straight to the bottom line—so negotiating better supplier rates or tightening petty cash controls steadily boosts margins.
E46: Current Values: | F46: Best Case | G46: Base Case | H46: Worst Case
C48: Changing Cells:
D49: Daily_Miscellaneous_expenses | E49: 526 | F49: 0 | G49: 300 | H49: 600
C50: Result Cells:
D51: Total_Daily_Profit | E51: 5384 | F51: 5910 | G51: 5610 | H51: 5310
C52: Notes: Current Values column represents values of changing cells at
C53: time Scenario Summary Report was created. Changing cells for each
C54: scenario are highlighted in gray.

Sheet 3.Probability Distributions 
A3: 1. Online Reservation (Poisson Distribution ) | J3: 2.Late Cancellation (poisson Distribution) | S3: 3.Number of Walkins (Empirical Distribution) | AD3: 4.Miscellaneous Expenses (Uniform Distribution)
B5: Reservation | C5: Cumulative probability | D5: Lower Limit | E5: Upper Limit | F5: Reservation | K5: Cancellation (K) | L5: Cumulative probability | M5: lower Limit | N5: Upper Limit | O5: Cancellation (K) | T5: walks in | U5: Frequency(days ) | V5: probability | W5: Cummulative probability | X5: Lower Limit | Y5: Upper Limit | Z5: walks in | AE5: Lower Limit | AF5: Upper Limit
B6: 0 | C6: =_xlfn.POISSON.DIST(B6,25,TRUE) -> 1.3887944e-11 | D6: 0 | E6: =C6 -> 1.3887944e-11 | F6: 0 | K6: 0 | L6: =_xlfn.POISSON.DIST(K6,3,TRUE) -> 0.049787068 | M6: 0 | N6: =L6 -> 0.049787068 | O6: 0 | T6: 0 | U6: 5 | V6: =U6/U$12 -> 0.05 | W6: =V6 -> 0.05 | X6: 0 | Y6: =W6 -> 0.05 | Z6: 0 | AE6: 0 | AF6: 600
B7: 1 | C7: =_xlfn.POISSON.DIST(B7,25,TRUE) -> 3.6108654e-10 | D7: =E6 -> 1.3887944e-11 | E7: =C7 -> 3.6108654e-10 | F7: 1 | K7: 1 | L7: =_xlfn.POISSON.DIST(K7,3,TRUE) -> 0.19914827 | M7: =N6 -> 0.049787068 | N7: =L7 -> 0.19914827 | O7: 1 | T7: 1 | U7: 10 | V7: =U7/U$12 -> 0.1 | W7: =W6+V7 -> 0.15 | X7: =Y6 -> 0.05 | Y7: =W7 -> 0.15 | Z7: 1
B8: 2 | C8: =_xlfn.POISSON.DIST(B8,25,TRUE) -> 4.701069e-09 | D8: =E7 -> 3.6108654e-10 | E8: =C8 -> 4.701069e-09 | F8: 2 | K8: 2 | L8: =_xlfn.POISSON.DIST(K8,3,TRUE) -> 0.42319008 | M8: =N7 -> 0.19914827 | N8: =L8 -> 0.42319008 | O8: 2 | T8: 2 | U8: 20 | V8: =U8/U$12 -> 0.2 | W8: =W7+V8 -> 0.35 | X8: =Y7 -> 0.15 | Y8: =W8 -> 0.35 | Z8: 2 | AD8: Rational For the Choice : We have no information beyond historical minimum and maximum expense values.
B9: 3 | C9: =_xlfn.POISSON.DIST(B9,25,TRUE) -> 4.0867589e-08 | D9: =E8 -> 4.701069e-09 | E9: =C9 -> 4.0867589e-08 | F9: 3 | K9: 3 | L9: =_xlfn.POISSON.DIST(K9,3,TRUE) -> 0.64723189 | M9: =N8 -> 0.42319008 | N9: =L9 -> 0.64723189 | O9: 3 | T9: 3 | U9: 25 | V9: =U9/U$12 -> 0.25 | W9: =W8+V9 -> 0.6 | X9: =Y8 -> 0.35 | Y9: =W9 -> 0.6 | Z9: 3
B10: 4 | C10: =_xlfn.POISSON.DIST(B10,25,TRUE) -> 2.6690834e-07 | D10: =E9 -> 4.0867589e-08 | E10: =C10 -> 2.6690834e-07 | F10: 4 | K10: 4 | L10: =_xlfn.POISSON.DIST(K10,3,TRUE) -> 0.81526324 | M10: =N9 -> 0.64723189 | N10: =L10 -> 0.81526324 | O10: 4 | T10: 4 | U10: 30 | V10: =U10/U$12 -> 0.3 | W10: =W9+V10 -> 0.9 | X10: =Y9 -> 0.6 | Y10: =W10 -> 0.9 | Z10: 4
B11: 5 | C11: =_xlfn.POISSON.DIST(B11,25,TRUE) -> 1.3971121e-06 | D11: =E10 -> 2.6690834e-07 | E11: =C11 -> 1.3971121e-06 | F11: 5 | K11: 5 | L11: =_xlfn.POISSON.DIST(K11,3,TRUE) -> 0.91608206 | M11: =N10 -> 0.81526324 | N11: =L11 -> 0.91608206 | O11: 5 | T11: 5 | U11: 10 | V11: =U11/U$12 -> 0.1 | W11: =W10+V11 -> 1 | X11: =Y10 -> 0.9 | Y11: =W11 -> 1 | Z11: 5
B12: 6 | C12: =_xlfn.POISSON.DIST(B12,25,TRUE) -> 6.1062945e-06 | D12: =E11 -> 1.3971121e-06 | E12: =C12 -> 6.1062945e-06 | F12: 6 | K12: 6 | L12: =_xlfn.POISSON.DIST(K12,3,TRUE) -> 0.96649146 | M12: =N11 -> 0.91608206 | N12: =L12 -> 0.96649146 | O12: 6 | U12: =SUM(U6:U11) -> 100 | V12: =SUM(V6:V11) -> 1
B13: 7 | C13: =_xlfn.POISSON.DIST(B13,25,TRUE) -> 2.2924803e-05 | D13: =E12 -> 6.1062945e-06 | E13: =C13 -> 2.2924803e-05 | F13: 7
B14: 8 | C14: =_xlfn.POISSON.DIST(B14,25,TRUE) -> 7.5482642e-05 | D14: =E13 -> 2.2924803e-05 | E14: =C14 -> 7.5482642e-05 | F14: 8 | K14: Rational For the Choice : it’s Discrete count of independent cancellation events: each late cancellation is a separate event, and multiple guests can cancel independently throughout the day. | T14: Rational For the Choice : The Walk-in arrivals showed no obvious theoretical fit, Rather than forcing a poor theoretical match, we use the relative frequency distribution from past walk-in counts to generate random draws
B15: 9 | C15: =_xlfn.POISSON.DIST(B15,25,TRUE) -> 0.00022147664 | D15: =E14 -> 7.5482642e-05 | E15: =C15 -> 0.00022147664 | F15: 9
B16: 10 | C16: =_xlfn.POISSON.DIST(B16,25,TRUE) -> 0.00058646163 | D16: =E15 -> 0.00022147664 | E16: =C16 -> 0.00058646163 | F16: 10
B17: 11 | C17: =_xlfn.POISSON.DIST(B17,25,TRUE) -> 0.001415973 | D17: =E16 -> 0.00058646163 | E17: =C17 -> 0.001415973 | F17: 11
B18: 12 | C18: =_xlfn.POISSON.DIST(B18,25,TRUE) -> 0.0031441216 | D18: =E17 -> 0.001415973 | E18: =C18 -> 0.0031441216 | F18: 12
B19: 13 | C19: =_xlfn.POISSON.DIST(B19,25,TRUE) -> 0.0064674844 | D19: =E18 -> 0.0031441216 | E19: =C19 -> 0.0064674844 | F19: 13
B20: 14 | C20: =_xlfn.POISSON.DIST(B20,25,TRUE) -> 0.012402061 | D20: =E19 -> 0.0064674844 | E20: =C20 -> 0.012402061 | F20: 14
B21: 15 | C21: =_xlfn.POISSON.DIST(B21,25,TRUE) -> 0.022293021 | D21: =E20 -> 0.012402061 | E21: =C21 -> 0.022293021 | F21: 15
B22: 16 | C22: =_xlfn.POISSON.DIST(B22,25,TRUE) -> 0.037747647 | D22: =E21 -> 0.022293021 | E22: =C22 -> 0.037747647 | F22: 16
B23: 17 | C23: =_xlfn.POISSON.DIST(B23,25,TRUE) -> 0.060475038 | D23: =E22 -> 0.037747647 | E23: =C23 -> 0.060475038 | F23: 17
B24: 18 | C24: =_xlfn.POISSON.DIST(B24,25,TRUE) -> 0.092040859 | D24: =E23 -> 0.060475038 | E24: =C24 -> 0.092040859 | F24: 18
B25: 19 | C25: =_xlfn.POISSON.DIST(B25,25,TRUE) -> 0.13357483 | D25: =E24 -> 0.092040859 | E25: =C25 -> 0.13357483 | F25: 19
B26: 20 | C26: =_xlfn.POISSON.DIST(B26,25,TRUE) -> 0.1854923 | D26: =E25 -> 0.13357483 | E26: =C26 -> 0.1854923 | F26: 20
... B56: 50 | C56: =_xlfn.POISSON.DIST(B56,25,TRUE) -> 0.99999665 | D56: =E55 -> 0.99999305 | E56: =C56 -> 0.99999665 | F56: 50
A58: mean = | B58: =AVERAGE(B6:B56) -> 25
B61: Rational For the Choice : it’s a Discrete count of independent arrivals per day: online bookings arrive one by one and are naturally modelled as counts over a fixed interval (one day)

Sheet 4.Simulation
B2: SIMULATION OF 1,000 TRIALS AT ROOM RATE $240 And LATE CANCELLATION $40 | L2: TRACKING CONVERGENCE OF OUTPUT MEANS | AA2: SIMULATION OF 1,000 TRIALS AT ROOM RATE $240 AND LATE CANCELLATION FEES $80 | AK2: TRACKING CONVERGENCE OF OUTPUT MEANS | BF2: SIMULATION OF 1,000 TRIALS AT ROOM RATE $280 AND LATE CANCELLATION FEES $40 | BP2: TRACKING CONVERGENCE OF OUTPUT MEANS | CD2: SIMULATION OF 1,000 TRIALS AT ROOM RATE $280 AND LATE CANCELLATION FEES $80 | CN2: TRACKING CONVERGENCE OF OUTPUT MEANS
B4: Simulation trial | C4: Daily Online Reservation | D4: Late Cancellation | E4: Number of Walkins | F4: Daily Miscellaneous expenses | G4: Number of Occupied rooms | H4: Total Sales Revenue | I4: Total Operation Cost | J4: Total Daily Profit | L4: Total Mean of Occupied Room | M4: Total mean of Sales Revenue | N4: Total mean of Operation Cost | O4: Mean Of Daily Profit | AA4: Simulation trial | AB4: Daily Online Reservation | AC4: Late Cancellation | AD4: Number of Walkins | AE4: Daily Miscellaneous expenses | AF4: Number of Occupied rooms | AG4: Total Sales Revenue | AH4: Total Operation Cost | AI4: Total Daily Profit | AK4: Total Mean Reservation | AL4: Total mean of Sales Revenue | AM4: Total mean of Operation Cost | AN4: Mean Total Daily Profit | BF4: Simulation trial | BG4: Daily Online Reservation | BH4: Late Cancellation | BI4: Number of Walkins | BJ4: Daily Miscellaneous expenses | BK4: Number of Occupied rooms | BL4: Total Sales Revenue | BM4: Total Operation Cost | BN4: Total Daily Profit | BP4: Total Mean Reservation | BQ4: Total mean of Sales Revenue | BR4: Total mean of Operation Cost | BS4: Mean of Total Daily Profit | CD4: Simulation trial | CE4: Daily Online Reservation | CF4: Late Cancellation | CG4: Number of Walkins | CH4: Daily Miscellaneous expenses | CI4: Number of Occupied rooms | CJ4: Total Sales Revenue | CK4: Total Operation Cost | CL4: Total Daily Profit | CN4: Total Mean Reservation | CO4: Total mean of Sales Revenue | CP4: Total mean of Operation Cost | CQ4: Mean Total Daily Profit
C5: ='1.c Model Simulated data'!H4 -> 21 | D5: ='1.c Model Simulated data'!H5 -> 6 | E5: ='1.c Model Simulated data'!H6 -> 3 | F5: ='1.c Model Simulated data'!H7 -> 294.87332 | G5: ='1.c Model Simulated data'!C4 -> 18 | H5: ='1.c Model Simulated data'!C5 -> 4560 | I5: ='1.c Model Simulated data'!C6 -> 4834.8733 | J5: ='1.c Model Simulated data'!C10 -> -274.87332 | AB5: ='1.c Model Simulated data'!H4 -> 21 | AC5: ='1.c Model Simulated data'!H5 -> 6 | AD5: ='1.c Model Simulated data'!H6 -> 3 | AE5: ='1.c Model Simulated data'!H7 -> 294.87332 | AF5: ='1.c Model Simulated data'!C4 -> 18 | AG5: ='1.c Model Simulated data'!C5 -> 4560 | AH5: ='1.c Model Simulated data'!C6 -> 4834.8733 | AI5: ='1.c Model Simulated data'!C10 -> -274.87332 | BG5: ='1.c Model Simulated data'!H4 -> 21 | BH5: ='1.c Model Simulated data'!H5 -> 6 | BI5: ='1.c Model Simulated data'!H6 -> 3 | BJ5: ='1.c Model Simulated data'!H7 -> 294.87332 | BK5: ='1.c Model Simulated data'!C4 -> 18 | BL5: ='1.c Model Simulated data'!C5 -> 4560 | BM5: ='1.c Model Simulated data'!C6 -> 4834.8733 | BN5: ='1.c Model Simulated data'!C10 -> -274.87332 | CE5: ='1.c Model Simulated data'!H4 -> 21 | CF5: ='1.c Model Simulated data'!H5 -> 6 | CG5: ='1.c Model Simulated data'!H6 -> 3 | CH5: ='1.c Model Simulated data'!H7 -> 294.87332 | CI5: ='1.c Model Simulated data'!C4 -> 18 | CJ5: ='1.c Model Simulated data'!C5 -> 4560 | CK5: ='1.c Model Simulated data'!C6 -> 4834.8733 | CL5: ='1.c Model Simulated data'!C10 -> -274.87332
B6: 1 | C6: 17 | D6: 4 | E6: 5 | F6: 16.840449 | G6: 18 | H6: 4480 | I6: 4556.8404 | J6: -76.840449 | L6: =AVERAGE(G$6:G6) -> 18 | M6: =AVERAGE(H$6:H6) -> 4480 | N6: =AVERAGE(I$6:I6) -> 4556.8404 | O6: =AVERAGE(J$6:J6) -> -76.840449 | AA6: 1 | AB6: 26 | AC6: 3 | AD6: 2 | AE6: 44.894376 | AF6: 25 | AG6: 6240 | AH6: 4794.8944 | AI6: 1445.1056 | AK6: =AVERAGE(AF$6:AF6) -> 25 | AL6: =AVERAGE(AG$6:AG6) -> 6240 | AM6: =AVERAGE(AH$6:AH6) -> 4794.8944 | AN6: =AVERAGE(AI$6:AI6) -> 1445.1056 | BF6: 1 | BG6: 23 | BH6: 2 | BI6: 1 | BJ6: 169.4301 | BK6: 22 | BL6: 6240 | BM6: 4829.4301 | BN6: 1410.5699 | BP6: =AVERAGE(BK$6:BK6) -> 22 | BQ6: =AVERAGE(BL$6:BL6) -> 6240 | BR6: =AVERAGE(BM$6:BM6) -> 4829.4301 | BS6: =AVERAGE(BN$6:BN6) -> 1410.5699 | CD6: 1 | CE6: 37 | CF6: 2 | CG6: 3 | CH6: 357.72244 | CI6: 38 | CJ6: 10800 | CK6: 5497.7224 | CL6: 5302.2776 | CN6: =AVERAGE(CI$6:CI6) -> 38 | CO6: =AVERAGE(CJ$6:CJ6) -> 10800 | CP6: =AVERAGE(CK$6:CK6) -> 5497.7224 | CQ6: =AVERAGE(CL$6:CL6) -> 5302.2776
B7: 2 | C7: 32 | D7: 1 | E7: 2 | F7: 503.74961 | G7: 33 | H7: 7960 | I7: 5493.7496 | J7: 2466.2504 | L7: =AVERAGE(G$6:G7) -> 25.5 | M7: =AVERAGE(H$6:H7) -> 6220 | N7: =AVERAGE(I$6:I7) -> 5025.295 | O7: =AVERAGE(J$6:J7) -> 1194.705 | AA7: 2 | AB7: 24 | AC7: 6 | AD7: 3 | AE7: 270.61157 | AF7: 21 | AG7: 5520 | AH7: 4900.6116 | AI7: 619.38843 | AK7: =AVERAGE(AF$6:AF7) -> 23 | AL7: =AVERAGE(AG$6:AG7) -> 5880 | AM7: =AVERAGE(AH$6:AH7) -> 4847.753 | AN7: =AVERAGE(AI$6:AI7) -> 1032.247 | BF7: 2 | BG7: 25 | BH7: 3 | BI7: 2 | BJ7: 271.48142 | BK7: 24 | BL7: 6840 | BM7: 4991.4814 | BN7: 1848.5186 | BP7: =AVERAGE(BK$6:BK7) -> 23 | BQ7: =AVERAGE(BL$6:BL7) -> 6540 | BR7: =AVERAGE(BM$6:BM7) -> 4910.4558 | BS7: =AVERAGE(BN$6:BN7) -> 1629.5442 | CD7: 2 | CE7: 19 | CF7: 4 | CG7: 1 | CH7: 195.40253 | CI7: 16 | CJ7: 4800 | CK7: 4675.4025 | CL7: 124.59747 | CN7: =AVERAGE(CI$6:CI7) -> 27 | CO7: =AVERAGE(CJ$6:CJ7) -> 7800 | CP7: =AVERAGE(CK$6:CK7) -> 5086.5625 | CQ7: =AVERAGE(CL$6:CL7) -> 2713.4375
B8: 3 | C8: 26 | D8: 4 | E8: 4 | F8: 574.32973 | G8: 26 | H8: 6400 | I8: 5354.3297 | J8: 1045.6703 | L8: =AVERAGE(G$6:G8) -> 25.666667 | M8: =AVERAGE(H$6:H8) -> 6280 | N8: =AVERAGE(I$6:I8) -> 5134.9733 | O8: =AVERAGE(J$6:J8) -> 1145.0267 | AA8: 3 | AB8: 31 | AC8: 5 | AD8: 4 | AE8: 33.323166 | AF8: 30 | AG8: 7600 | AH8: 4933.3232 | AI8: 2666.6768 | AK8: =AVERAGE(AF$6:AF8) -> 25.333333 | AL8: =AVERAGE(AG$6:AG8) -> 6453.3333 | AM8: =AVERAGE(AH$6:AH8) -> 4876.2764 | AN8: =AVERAGE(AI$6:AI8) -> 1577.057 | BF8: 3 | BG8: 29 | BH8: 3 | BI8: 3 | BJ8: 94.167624 | BK8: 29 | BL8: 8240 | BM8: 4964.1676 | BN8: 3275.8324 | BP8: =AVERAGE(BK$6:BK8) -> 25 | BQ8: =AVERAGE(BL$6:BL8) -> 7106.6667 | BR8: =AVERAGE(BM$6:BM8) -> 4928.3597 | BS8: =AVERAGE(BN$6:BN8) -> 2178.307 | CD8: 3 | CE8: 30 | CF8: 3 | CG8: 4 | CH8: 226.90038 | CI8: 31 | CJ8: 8920 | CK8: 5156.9004 | CL8: 3763.0996 | CN8: =AVERAGE(CI$6:CI8) -> 28.333333 | CO8: =AVERAGE(CJ$6:CJ8) -> 8173.3333 | CP8: =AVERAGE(CK$6:CK8) -> 5110.0085 | CQ8: =AVERAGE(CL$6:CL8) -> 3063.3249
B9: 4 | C9: 30 | D9: 4 | E9: 2 | F9: 541.50226 | G9: 28 | H9: 6880 | I9: 5381.5023 | J9: 1498.4977 | L9: =AVERAGE(G$6:G9) -> 26.25 | M9: =AVERAGE(H$6:H9) -> 6430 | N9: =AVERAGE(I$6:I9) -> 5196.6055 | O9: =AVERAGE(J$6:J9) -> 1233.3945 | AA9: 4 | AB9: 24 | AC9: 5 | AD9: 1 | AE9: 220.79702 | AF9: 20 | AG9: 5200 | AH9: 4820.797 | AI9: 379.20298 | AK9: =AVERAGE(AF$6:AF9) -> 24 | AL9: =AVERAGE(AG$6:AG9) -> 6140 | AM9: =AVERAGE(AH$6:AH9) -> 4862.4065 | AN9: =AVERAGE(AI$6:AI9) -> 1277.5935 | BF9: 4 | BG9: 21 | BH9: 1 | BI9: 5 | BJ9: 58.469381 | BK9: 25 | BL9: 7040 | BM9: 4808.4694 | BN9: 2231.5306 | BP9: =AVERAGE(BK$6:BK9) -> 25 | BQ9: =AVERAGE(BL$6:BL9) -> 7090 | BR9: =AVERAGE(BM$6:BM9) -> 4898.3871 | BS9: =AVERAGE(BN$6:BN9) -> 2191.6129 | CD9: 4 | CE9: 25 | CF9: 3 | CG9: 2 | CH9: 300.15523 | CI9: 24 | CJ9: 6960 | CK9: 5020.1552 | CL9: 1939.8448 | CN9: =AVERAGE(CI$6:CI9) -> 27.25 | CO9: =AVERAGE(CJ$6:CJ9) -> 7870 | CP9: =AVERAGE(CK$6:CK9) -> 5087.5451 | CQ9: =AVERAGE(CL$6:CL9) -> 2782.4549
B10: 5 | C10: 21 | D10: 3 | E10: 3 | F10: 374.69203 | G10: 21 | H10: 5160 | I10: 5004.692 | J10: 155.30797 | L10: =AVERAGE(G$6:G10) -> 25.2 | M10: =AVERAGE(H$6:H10) -> 6176 | N10: =AVERAGE(I$6:I10) -> 5158.2228 | O10: =AVERAGE(J$6:J10) -> 1017.7772 | AA10: 5 | AB10: 31 | AC10: 4 | AD10: 4 | AE10: 264.87319 | AF10: 31 | AG10: 7760 | AH10: 5194.8732 | AI10: 2565.1268 | AK10: =AVERAGE(AF$6:AF10) -> 25.4 | AL10: =AVERAGE(AG$6:AG10) -> 6464 | AM10: =AVERAGE(AH$6:AH10) -> 4928.8999 | AN10: =AVERAGE(AI$6:AI10) -> 1535.1001 | BF10: 5 | BG10: 37 | BH10: 3 | BI10: 5 | BJ10: 479.02976 | BK10: 39 | BL10: 11040 | BM10: 5649.0298 | BN10: 5390.9702 | BP10: =AVERAGE(BK$6:BK10) -> 27.8 | BQ10: =AVERAGE(BL$6:BL10) -> 7880 | BR10: =AVERAGE(BM$6:BM10) -> 5048.5157 | BS10: =AVERAGE(BN$6:BN10) -> 2831.4843 | CD10: 5 | CE10: 29 | CF10: 2 | CG10: 1 | CH10: 335.68041 | CI10: 28 | CJ10: 8000 | CK10: 5175.6804 | CL10: 2824.3196 | CN10: =AVERAGE(CI$6:CI10) -> 27.4 | CO10: =AVERAGE(CJ$6:CJ10) -> 7896 | CP10: =AVERAGE(CK$6:CK10) -> 5105.1722 | CQ10: =AVERAGE(CL$6:CL10) -> 2790.8278
B11: 6 | C11: 25 | D11: 4 | E11: 2 | F11: 440.84425 | G11: 23 | H11: 5680 | I11: 5130.8442 | J11: 549.15575 | L11: =AVERAGE(G$6:G11) -> 24.833333 | M11: =AVERAGE(H$6:H11) -> 6093.3333 | N11: =AVERAGE(I$6:I11) -> 5153.6597 | O11: =AVERAGE(J$6:J11) -> 939.67361 | AA11: 6 | AB11: 33 | AC11: 5 | AD11: 3 | AE11: 249.14814 | AF11: 31 | AG11: 7840 | AH11: 5179.1481 | AI11: 2660.8519 | AK11: =AVERAGE(AF$6:AF11) -> 26.333333 | AL11: =AVERAGE(AG$6:AG11) -> 6693.3333 | AM11: =AVERAGE(AH$6:AH11) -> 4970.6079 | AN11: =AVERAGE(AI$6:AI11) -> 1722.7254 | BF11: 6 | BG11: 20 | BH11: 1 | BI11: 4 | BJ11: 423.67804 | BK11: 23 | BL11: 6480 | BM11: 5113.678 | BN11: 1366.322 | BP11: =AVERAGE(BK$6:BK11) -> 27 | BQ11: =AVERAGE(BL$6:BL11) -> 7646.6667 | BR11: =AVERAGE(BM$6:BM11) -> 5059.3761 | BS11: =AVERAGE(BN$6:BN11) -> 2587.2906 | CD11: 6 | CE11: 25 | CF11: 2 | CG11: 4 | CH11: 216.39583 | CI11: 27 | CJ11: 7720 | CK11: 5026.3958 | CL11: 2693.6042 | CN11: =AVERAGE(CI$6:CI11) -> 27.333333 | CO11: =AVERAGE(CJ$6:CJ11) -> 7866.6667 | CP11: =AVERAGE(CK$6:CK11) -> 5092.0428 | CQ11: =AVERAGE(CL$6:CL11) -> 2774.6239
B12: 7 | C12: 23 | D12: 3 | E12: 3 | F12: 287.59377 | G12: 23 | H12: 5640 | I12: 4977.5938 | J12: 662.40623 | L12: =AVERAGE(G$6:G12) -> 24.571429 | M12: =AVERAGE(H$6:H12) -> 6028.5714 | N12: =AVERAGE(I$6:I12) -> 5128.5074 | O12: =AVERAGE(J$6:J12) -> 900.06398 | AA12: 7 | AB12: 45 | AC12: 2 | AD12: 3 | AE12: 512.20742 | AF12: 46 | AG12: 11200 | AH12: 5892.2074 | AI12: 5307.7926 | AK12: =AVERAGE(AF$6:AF12) -> 29.142857 | AL12: =AVERAGE(AG$6:AG12) -> 7337.1429 | AM12: =AVERAGE(AH$6:AH12) -> 5102.265 | AN12: =AVERAGE(AI$6:AI12) -> 2234.8779 | BF12: 7 | BG12: 27 | BH12: 2 | BI12: 1 | BJ12: 159.58149 | BK12: 26 | BL12: 7360 | BM12: 4939.5815 | BN12: 2420.4185 | BP12: =AVERAGE(BK$6:BK12) -> 26.857143 | BQ12: =AVERAGE(BL$6:BL12) -> 7605.7143 | BR12: =AVERAGE(BM$6:BM12) -> 5042.2625 | BS12: =AVERAGE(BN$6:BN12) -> 2563.4517 | CD12: 7 | CE12: 30 | CF12: 3 | CG12: 5 | CH12: 204.83687 | CI12: 32 | CJ12: 9200 | CK12: 5164.8369 | CL12: 4035.1631 | CN12: =AVERAGE(CI$6:CI12) -> 28 | CO12: =AVERAGE(CJ$6:CJ12) -> 8057.1429 | CP12: =AVERAGE(CK$6:CK12) -> 5102.442 | CQ12: =AVERAGE(CL$6:CL12) -> 2954.7009
B13: 8 | C13: 28 | D13: 1 | E13: 3 | F13: 116.33271 | G13: 30 | H13: 7240 | I13: 5016.3327 | J13: 2223.6673 | L13: =AVERAGE(G$6:G13) -> 25.25 | M13: =AVERAGE(H$6:H13) -> 6180 | N13: =AVERAGE(I$6:I13) -> 5114.4856 | O13: =AVERAGE(J$6:J13) -> 1065.5144 | AA13: 8 | AB13: 27 | AC13: 2 | AD13: 3 | AE13: 232.79279 | AF13: 28 | AG13: 6880 | AH13: 5072.7928 | AI13: 1807.2072 | AK13: =AVERAGE(AF$6:AF13) -> 29 | AL13: =AVERAGE(AG$6:AG13) -> 7280 | AM13: =AVERAGE(AH$6:AH13) -> 5098.581 | AN13: =AVERAGE(AI$6:AI13) -> 2181.419 | BF13: 8 | BG13: 28 | BH13: 4 | BI13: 1 | BJ13: 373.2935 | BK13: 25 | BL13: 7160 | BM13: 5123.2935 | BN13: 2036.7065 | BP13: =AVERAGE(BK$6:BK13) -> 26.625 | BQ13: =AVERAGE(BL$6:BL13) -> 7550 | BR13: =AVERAGE(BM$6:BM13) -> 5052.3914 | BS13: =AVERAGE(BN$6:BN13) -> 2497.6086 | CD13: 8 | CE13: 20 | CF13: 3 | CG13: 2 | CH13: 296.4066 | CI13: 19 | CJ13: 5560 | CK13: 4866.4066 | CL13: 693.5934 | CN13: =AVERAGE(CI$6:CI13) -> 26.875 | CO13: =AVERAGE(CJ$6:CJ13) -> 7745 | CP13: =AVERAGE(CK$6:CK13) -> 5072.9375 | CQ13: =AVERAGE(CL$6:CL13) -> 2672.0625
B14: 9 | C14: 24 | D14: 3 | E14: 0 | F14: 437.17272 | G14: 21 | H14: 5160 | I14: 5067.1727 | J14: 92.827276 | L14: =AVERAGE(G$6:G14) -> 24.777778 | M14: =AVERAGE(H$6:H14) -> 6066.6667 | N14: =AVERAGE(I$6:I14) -> 5109.2286 | O14: =AVERAGE(J$6:J14) -> 957.43805 | AA14: 9 | AB14: 28 | AC14: 0 | AD14: 5 | AE14: 239.94946 | AF14: 33 | AG14: 7920 | AH14: 5229.9495 | AI14: 2690.0505 | AK14: =AVERAGE(AF$6:AF14) -> 29.444444 | AL14: =AVERAGE(AG$6:AG14) -> 7351.1111 | AM14: =AVERAGE(AH$6:AH14) -> 5113.1775 | AN14: =AVERAGE(AI$6:AI14) -> 2237.9337 | BF14: 9 | BG14: 27 | BH14: 3 | BI14: 5 | BJ14: 385.74 | BK14: 29 | BL14: 8240 | BM14: 5255.74 | BN14: 2984.26 | BP14: =AVERAGE(BK$6:BK14) -> 26.888889 | BQ14: =AVERAGE(BL$6:BL14) -> 7626.6667 | BR14: =AVERAGE(BM$6:BM14) -> 5074.9857 | BS14: =AVERAGE(BN$6:BN14) -> 2551.681 | CD14: 9 | CE14: 24 | CF14: 3 | CG14: 1 | CH14: 331.10833 | CI14: 22 | CJ14: 6400 | CK14: 4991.1083 | CL14: 1408.8917 | CN14: =AVERAGE(CI$6:CI14) -> 26.333333 | CO14: =AVERAGE(CJ$6:CJ14) -> 7595.5556 | CP14: =AVERAGE(CK$6:CK14) -> 5063.8454 | CQ14: =AVERAGE(CL$6:CL14) -> 2531.7102
B15: 10 | C15: 28 | D15: 2 | E15: 4 | F15: 236.79772 | G15: 30 | H15: 7280 | I15: 5136.7977 | J15: 2143.2023 | L15: =AVERAGE(G$6:G15) -> 25.3 | M15: =AVERAGE(H$6:H15) -> 6188 | N15: =AVERAGE(I$6:I15) -> 5111.9855 | O15: =AVERAGE(J$6:J15) -> 1076.0145 | AA15: 10 | AB15: 21 | AC15: 3 | AD15: 2 | AE15: 157.38254 | AF15: 20 | AG15: 5040 | AH15: 4757.3825 | AI15: 282.61746 | AK15: =AVERAGE(AF$6:AF15) -> 28.5 | AL15: =AVERAGE(AG$6:AG15) -> 7120 | AM15: =AVERAGE(AH$6:AH15) -> 5077.598 | AN15: =AVERAGE(AI$6:AI15) -> 2042.402 | BF15: 10 | BG15: 22 | BH15: 4 | BI15: 4 | BJ15: 548.77077 | BK15: 22 | BL15: 6320 | BM15: 5208.7708 | BN15: 1111.2292 | BP15: =AVERAGE(BK$6:BK15) -> 26.4 | BQ15: =AVERAGE(BL$6:BL15) -> 7496 | BR15: =AVERAGE(BM$6:BM15) -> 5088.3642 | BS15: =AVERAGE(BN$6:BN15) -> 2407.6358 | CD15: 10 | CE15: 24 | CF15: 2 | CG15: 4 | CH15: 6.0546376 | CI15: 26 | CJ15: 7440 | CK15: 4786.0546 | CL15: 2653.9454 | CN15: =AVERAGE(CI$6:CI15) -> 26.3 | CO15: =AVERAGE(CJ$6:CJ15) -> 7580 | CP15: =AVERAGE(CK$6:CK15) -> 5036.0663 | CQ15: =AVERAGE(CL$6:CL15) -> 2543.9337
B16: 11 | C16: 23 | D16: 3 | E16: 1 | F16: 231.96776 | G16: 21 | H16: 5160 | I16: 4861.9678 | J16: 298.03224 | L16: =AVERAGE(G$6:G16) -> 24.909091 | M16: =AVERAGE(H$6:H16) -> 6094.5455 | N16: =AVERAGE(I$6:I16) -> 5089.2566 | O16: =AVERAGE(J$6:J16) -> 1005.2888 | AA16: 11 | AB16: 18 | AC16: 1 | AD16: 1 | AE16: 440.01604 | AF16: 18 | AG16: 4400 | AH16: 4980.016 | AI16: -580.01604 | AK16: =AVERAGE(AF$6:AF16) -> 27.545455 | AL16: =AVERAGE(AG$6:AG16) -> 6872.7273 | AM16: =AVERAGE(AH$6:AH16) -> 5068.7269 | AN16: =AVERAGE(AI$6:AI16) -> 1804.0004 | BF16: 11 | BG16: 24 | BH16: 4 | BI16: 3 | BJ16: 349.64509 | BK16: 23 | BL16: 6600 | BM16: 5039.6451 | BN16: 1560.3549 | BP16: =AVERAGE(BK$6:BK16) -> 26.090909 | BQ16: =AVERAGE(BL$6:BL16) -> 7414.5455 | BR16: =AVERAGE(BM$6:BM16) -> 5083.9352 | BS16: =AVERAGE(BN$6:BN16) -> 2330.6103 | CD16: 11 | CE16: 21 | CF16: 4 | CG16: 4 | CH16: 151.67569 | CI16: 21 | CJ16: 6200 | CK16: 4781.6757 | CL16: 1418.3243 | CN16: =AVERAGE(CI$6:CI16) -> 25.818182 | CO16: =AVERAGE(CJ$6:CJ16) -> 7454.5455 | CP16: =AVERAGE(CK$6:CK16) -> 5012.9399 | CQ16: =AVERAGE(CL$6:CL16) -> 2441.6055
B17: 12 | C17: 24 | D17: 2 | E17: 4 | F17: 298.19429 | G17: 26 | H17: 6320 | I17: 5078.1943 | J17: 1241.8057 | L17: =AVERAGE(G$6:G17) -> 25 | M17: =AVERAGE(H$6:H17) -> 6113.3333 | N17: =AVERAGE(I$6:I17) -> 5088.3348 | O17: =AVERAGE(J$6:J17) -> 1024.9986 | AA17: 12 | AB17: 23 | AC17: 6 | AD17: 3 | AE17: 192.83343 | AF17: 20 | AG17: 5280 | AH17: 4792.8334 | AI17: 487.16657 | AK17: =AVERAGE(AF$6:AF17) -> 26.916667 | AL17: =AVERAGE(AG$6:AG17) -> 6740 | AM17: =AVERAGE(AH$6:AH17) -> 5045.7358 | AN17: =AVERAGE(AI$6:AI17) -> 1694.2642 | BF17: 12 | BG17: 22 | BH17: 1 | BI17: 3 | BJ17: 594.00178 | BK17: 24 | BL17: 6760 | BM17: 5314.0018 | BN17: 1445.9982 | BP17: =AVERAGE(BK$6:BK17) -> 25.916667 | BQ17: =AVERAGE(BL$6:BL17) -> 7360 | BR17: =AVERAGE(BM$6:BM17) -> 5103.1074 | BS17: =AVERAGE(BN$6:BN17) -> 2256.8926 | CD17: 12 | CE17: 24 | CF17: 0 | CG17: 0 | CH17: 300.70837 | CI17: 24 | CJ17: 6720 | CK17: 5020.7084 | CL17: 1699.2916 | CN17: =AVERAGE(CI$6:CI17) -> 25.666667 | CO17: =AVERAGE(CJ$6:CJ17) -> 7393.3333 | CP17: =AVERAGE(CK$6:CK17) -> 5013.5873 | CQ17: =AVERAGE(CL$6:CL17) -> 2379.7461
... B1005: 1000 | C1005: 25 | D1005: 6 | E1005: 2 | F1005: 454.32503 | G1005: 21 | H1005: 5280 | I1005: 5084.325 | J1005: 195.67497 | L1005: =AVERAGE(G$6:G1005) -> 25.203 | M1005: =AVERAGE(H$6:H1005) -> 6165.52 | N1005: =AVERAGE(I$6:I1005) -> 5052.4344 | O1005: =AVERAGE(J$6:J1005) -> 1113.0856 | AA1005: 1000 | AB1005: 30 | AC1005: 5 | AD1005: 1 | AE1005: 57.323755 | AF1005: 26 | AG1005: 6640 | AH1005: 4837.3238 | AI1005: 1802.6762 | AK1005: =AVERAGE(AF$6:AF1005) -> 25.383 | AL1005: =AVERAGE(AG$6:AG1005) -> 6326.56 | AM1005: =AVERAGE(AH$6:AH1005) -> 5060.3392 | AN1005: =AVERAGE(AI$6:AI1005) -> 1266.2208 | BF1005: 1000 | BG1005: 22 | BH1005: 3 | BI1005: 4 | BJ1005: 66.708567 | BK1005: 23 | BL1005: 6560 | BM1005: 4756.7086 | BN1005: 1803.2914 | BP1005: =AVERAGE(BK$6:BK1005) -> 24.952 | BQ1005: =AVERAGE(BL$6:BL1005) -> 7108.36 | BR1005: =AVERAGE(BM$6:BM1005) -> 5057.0142 | BS1005: =AVERAGE(BN$6:BN1005) -> 2051.3458 | CD1005: 1000 | CE1005: 28 | CF1005: 6 | CG1005: 3 | CH1005: 572.37772 | CI1005: 25 | CJ1005: 7480 | CK1005: 5322.3777 | CL1005: 2157.6223 | CN1005: =AVERAGE(CI$6:CI1005) -> 24.804 | CO1005: =AVERAGE(CJ$6:CJ1005) -> 7182.96 | CP1005: =AVERAGE(CK$6:CK1005) -> 5047.995 | CQ1005: =AVERAGE(CL$6:CL1005) -> 2134.965
B1006: MIN | C1006: =MIN(C6:C1005) -> 11 | D1006: =MIN(D6:D1005) -> 0 | E1006: =MIN(E6:E1005) -> 0 | F1006: =MIN(F6:F1005) -> 2.1830165 | G1006: =MIN(G6:G1005) -> 9 | H1006: =MIN(H6:H1005) -> 2400 | I1006: =MIN(I6:I1005) -> 4471.2762 | J1006: =MIN(J6:J1005) -> -2259.5724 | AA1006: MIN | AB1006: =MIN(AB6:AB1005) -> 8 | AC1006: =MIN(AC6:AC1005) -> 0 | AD1006: =MIN(AD6:AD1005) -> 0 | AE1006: =MIN(AE6:AE1005) -> 0.95042586 | AF1006: =MIN(AF6:AF1005) -> 7 | AG1006: =MIN(AG6:AG1005) -> 1840 | AH1006: =MIN(AH6:AH1005) -> 4293.0283 | AI1006: =MIN(AI6:AI1005) -> -2686.5657 | BF1006: MIN | BG1006: =MIN(BG6:BG1005) -> 11 | BH1006: =MIN(BH6:BH1005) -> 0 | BI1006: =MIN(BI6:BI1005) -> 0 | BJ1006: =MIN(BJ6:BJ1005) -> 0.020862097 | BK1006: =MIN(BK6:BK1005) -> 9 | BL1006: =MIN(BL6:BL1005) -> 2760 | BM1006: =MIN(BM6:BM1005) -> 4440.6572 | BN1006: =MIN(BN6:BN1005) -> -1695.2392 | CD1006: MIN | CE1006: =MIN(CE6:CE1005) -> 10 | CF1006: =MIN(CF6:CF1005) -> 0 | CG1006: =MIN(CG6:CG1005) -> 0 | CH1006: =MIN(CH6:CH1005) -> 0.050455169 | CI1006: =MIN(CI6:CI1005) -> 10 | CJ1006: =MIN(CJ6:CJ1005) -> 2960 | CK1006: =MIN(CK6:CK1005) -> 4315.0896 | CL1006: =MIN(CL6:CL1005) -> -1562.2335
B1007: MAX | C1007: =MAX(C6:C1005) -> 43 | D1007: =MAX(D6:D1005) -> 6 | E1007: =MAX(E6:E1005) -> 5 | F1007: =MAX(F6:F1005) -> 599.9025 | G1007: =MAX(G6:G1005) -> 43 | H1007: =MAX(H6:H1005) -> 10360 | I1007: =MAX(I6:I1005) -> 5838.6775 | J1007: =MAX(J6:J1005) -> 4523.2521 | AA1007: MAX | AB1007: =MAX(AB6:AB1005) -> 45 | AC1007: =MAX(AC6:AC1005) -> 6 | AD1007: =MAX(AD6:AD1005) -> 5 | AE1007: =MAX(AE6:AE1005) -> 599.98753 | AF1007: =MAX(AF6:AF1005) -> 46 | AG1007: =MAX(AG6:AG1005) -> 11200 | AH1007: =MAX(AH6:AH1005) -> 5892.2074 | AI1007: =MAX(AI6:AI1005) -> 5497.4948 | BF1007: MAX | BG1007: =MAX(BG6:BG1005) -> 43 | BH1007: =MAX(BH6:BH1005) -> 6 | BI1007: =MAX(BI6:BI1005) -> 5 | BJ1007: =MAX(BJ6:BJ1005) -> 599.95671 | BK1007: =MAX(BK6:BK1005) -> 43 | BL1007: =MAX(BL6:BL1005) -> 12080 | BM1007: =MAX(BM6:BM1005) -> 5812.5518 | BN1007: =MAX(BN6:BN1005) -> 6342.7713 | CD1007: MAX | CE1007: =MAX(CE6:CE1005) -> 43 | CF1007: =MAX(CF6:CF1005) -> 6 | CG1007: =MAX(CG6:CG1005) -> 5 | CH1007: =MAX(CH6:CH1005) -> 599.14519 | CI1007: =MAX(CI6:CI1005) -> 45 | CJ1007: =MAX(CJ6:CJ1005) -> 12600 | CK1007: =MAX(CK6:CK1005) -> 5760.1731 | CL1007: =MAX(CL6:CL1005) -> 7236.9732
B1008: AVER | C1008: =AVERAGE(C6:C1005) -> 25.185 | D1008: =AVERAGE(D6:D1005) -> 2.92 | E1008: =AVERAGE(E6:E1005) -> 2.938 | F1008: =AVERAGE(F6:F1005) -> 296.34437 | G1008: =AVERAGE(G6:G1005) -> 25.203 | H1008: =AVERAGE(H6:H1005) -> 6165.52 | I1008: =AVERAGE(I6:I1005) -> 5052.4344 | J1008: =AVERAGE(J6:J1005) -> 1113.0856 | AA1008: AVER | AB1008: =AVERAGE(AB6:AB1005) -> 25.35 | AC1008: =AVERAGE(AC6:AC1005) -> 2.933 | AD1008: =AVERAGE(AD6:AD1005) -> 2.966 | AE1008: =AVERAGE(AE6:AE1005) -> 298.84919 | AF1008: =AVERAGE(AF6:AF1005) -> 25.383 | AG1008: =AVERAGE(AG6:AG1005) -> 6326.56 | AH1008: =AVERAGE(AH6:AH1005) -> 5060.3392 | AI1008: =AVERAGE(AI6:AI1005) -> 1266.2208 | BF1008: AVER | BG1008: =AVERAGE(BG6:BG1005) -> 25.019 | BH1008: =AVERAGE(BH6:BH1005) -> 3.045 | BI1008: =AVERAGE(BI6:BI1005) -> 2.978 | BJ1008: =AVERAGE(BJ6:BJ1005) -> 308.4542 | BK1008: =AVERAGE(BK6:BK1005) -> 24.952 | BL1008: =AVERAGE(BL6:BL1005) -> 7108.36 | BM1008: =AVERAGE(BM6:BM1005) -> 5057.0142 | BN1008: =AVERAGE(BN6:BN1005) -> 2051.3458 | CD1008: AVER | CE1008: =AVERAGE(CE6:CE1005) -> 24.845 | CF1008: =AVERAGE(CF6:CF1005) -> 2.973 | CG1008: =AVERAGE(CG6:CG1005) -> 2.932 | CH1008: =AVERAGE(CH6:CH1005) -> 303.87497 | CI1008: =AVERAGE(CI6:CI1005) -> 24.804 | CJ1008: =AVERAGE(CJ6:CJ1005) -> 7182.96 | CK1008: =AVERAGE(CK6:CK1005) -> 5047.995 | CL1008: =AVERAGE(CL6:CL1005) -> 2134.965

Sheet 4.a Simulation Summary
C9: DESCRIPTIVE STATISTICS (based on SIMULATED OUTPUT -constant values)
C14: ` | D14: Daily Profit ("$') when Room Rate and Late Cancellation is | F14: Daily Profit ("$') when Room Rate and Late Cancellation is
D16: $240 and $40 | E16: $240 and $80 | F16: $280 and $40 | G16: $280 and $80
C17: Mean | D17: =AVERAGE('4.Simulation'!J6:J1005) -> 1113.0856 | E17: =AVERAGE('4.Simulation'!AI6:AI1005) -> 1266.2208 | F17: =AVERAGE('4.Simulation'!BN6:BN1005) -> 2051.3458 | G17: =AVERAGE('4.Simulation'!CL6:CL1005) -> 2134.965
C18: Standard Deviation | D18: =_xlfn.STDEV.S('4.Simulation'!J6:J1005) -> 1122.0815 | E18: =_xlfn.STDEV.S('4.Simulation'!AI6:AI1005) -> 1138.1297 | F18: =_xlfn.STDEV.S('4.Simulation'!BN6:BN1005) -> 1343.1217 | G18: =_xlfn.STDEV.S('4.Simulation'!CL6:CL1005) -> 1302.524
C19: Minimum | D19: =MIN('4.Simulation'!J6:J1005) -> -2259.5724 | E19: =MIN('4.Simulation'!AI6:AI1005) -> -2686.5657 | F19: =MIN('4.Simulation'!BN6:BN1005) -> -1695.2392 | G19: =MIN('4.Simulation'!CL6:CL1005) -> -1562.2335
C20: Maximum | D20: =MAX('4.Simulation'!J6:J1005) -> 4523.2521 | E20: =MAX('4.Simulation'!AI6:AI1005) -> 5497.4948 | F20: =MAX('4.Simulation'!BN6:BN1005) -> 6342.7713 | G20: =MAX('4.Simulation'!CL6:CL1005) -> 7236.9732
C21: Probability of loss | D21: =COUNTIF('4.Simulation'!J6:J1005,"<0")/1000 -> 0.153 | E21: =COUNTIF('4.Simulation'!AI6:AI1005,"<0")/1000 -> 0.123 | F21: =COUNTIF('4.Simulation'!BN6:BN1005,"<0")/1000 -> 0.053 | G21: =COUNTIF('4.Simulation'!CL6:CL1005,"<0")/1000 -> 0.047
C23: 95% Confidence limits for the mean
C25: UCL | D25: =D$17+_xlfn.T.INV.2T(0.05,1000-1)*D$18/SQRT(1000) -> 1182.716 | E25: =E$17+_xlfn.T.INV.2T(0.05,1000-1)*E$18/SQRT(1000) -> 1336.8471 | F25: =F$17+_xlfn.T.INV.2T(0.05,1000-1)*F$18/SQRT(1000) -> 2134.6928 | G25: =G$17+_xlfn.T.INV.2T(0.05,1000-1)*G$18/SQRT(1000) -> 2215.7927
C26: LCL | D26: =D$17-_xlfn.T.INV.2T(0.05,1000-1)*D$18/SQRT(1000) -> 1043.4552 | E26: =E$17-_xlfn.T.INV.2T(0.05,1000-1)*E$18/SQRT(1000) -> 1195.5945 | F26: =F$17-_xlfn.T.INV.2T(0.05,1000-1)*F$18/SQRT(1000) -> 1967.9988 | G26: =G$17-_xlfn.T.INV.2T(0.05,1000-1)*G$18/SQRT(1000) -> 2054.1373
C29: Lower Quartile | D29: =QUARTILE('4.Simulation'!J6:J1005,1) -> 328.88525 | E29: =QUARTILE('4.Simulation'!AI6:AI1005,1) -> 510.18861 | F29: =QUARTILE('4.Simulation'!BN6:BN1005,1) -> 1116.023 | G29: =QUARTILE('4.Simulation'!CL6:CL1005,1) -> 1265.0336
C30: Upper Quartile | D30: =QUARTILE('4.Simulation'!J6:J1005,3) -> 1840.72 | E30: =QUARTILE('4.Simulation'!AI6:AI1005,3) -> 2028.2549 | F30: =QUARTILE('4.Simulation'!BN6:BN1005,3) -> 2960.2115 | G30: =QUARTILE('4.Simulation'!CL6:CL1005,3) -> 2903.7141
C31: IQR | D31: =D30-D29 -> 1511.8348 | E31: =E30-E29 -> 1518.0663 | F31: =F30-F29 -> 1844.1885 | G31: =G30-G29 -> 1638.6804
C32: 90th Percentile | D32: =PERCENTILE('4.Simulation'!J6:J1005,0.9) -> 2483.8202 | E32: =PERCENTILE('4.Simulation'!AI6:AI1005,0.9) -> 2718.17 | F32: =PERCENTILE('4.Simulation'!BN6:BN1005,0.9) -> 3803.1941 | G32: =PERCENTILE('4.Simulation'!CL6:CL1005,0.9) -> 3805.4102
C33: 10th Percentile | D33: =PERCENTILE('4.Simulation'!J6:J1005,0.1) -> -303.53433 | E33: =PERCENTILE('4.Simulation'!AI6:AI1005,0.1) -> -111.18228 | F33: =PERCENTILE('4.Simulation'!BN6:BN1005,0.1) -> 387.6641 | G33: =PERCENTILE('4.Simulation'!CL6:CL1005,0.1) -> 457.6242
J41: For Room Rate $240 and $40 | M41: Bin | N41: Frequency | O41: % Frequency | BB41: Room Rate $280 and $80 | BG41: Bin | BH41: Frequency | BI41: % Frequency
M42: -2500 | N42: 0 | O42: =N42/N$60 -> 0 | W42: Room Rate $240 and $80 | AA42: Bin | AB42: Frequency | AC42: % Frequency | AJ42: Room Rate $280 and $40 | AO42: Bin | AP42: Frequency | AQ42: % Frequency | BG42: -3000 | BH42: 0 | BI42: =BH42/BH$64 -> 0
J43: Mean | K43: 1113.0856 | M43: -2000 | N43: 2 | O43: =N43/N$60 -> 0.002 | AA43: -3000 | AB43: 0 | AC43: =AB43/AB$63 -> 0 | AO43: -3000 | AP43: 0 | AQ43: =AP43/AP$63 -> 0 | BB43: Mean | BC43: 2134.965 | BG43: -2500 | BH43: 0 | BI43: =BH43/BH$64 -> 0
J44: Standard Error | K44: 35.483332 | M44: -1500 | N44: 5 | O44: =N44/N$60 -> 0.005 | W44: Mean | X44: 1266.2208 | AA44: -2500 | AB44: 1 | AC44: =AB44/AB$63 -> 0.001 | AJ44: Mean | AK44: 2051.3458 | AO44: -2500 | AP44: 0 | AQ44: =AP44/AP$63 -> 0 | BB44: Standard Error | BC44: 41.189425 | BG44: -2000 | BH44: 0 | BI44: =BH44/BH$64 -> 0
J45: Median | K45: 1090.1625 | M45: -1000 | N45: 19 | O45: =N45/N$60 -> 0.019 | W45: Standard Error | X45: 35.990822 | AA45: -2000 | AB45: 1 | AC45: =AB45/AB$63 -> 0.001 | AJ45: Standard Error | AK45: 42.473238 | AO45: -2000 | AP45: 0 | AQ45: =AP45/AP$63 -> 0 | BB45: Median | BC45: 2100.5588 | BG45: -1500 | BH45: 1 | BI45: =BH45/BH$64 -> 0.001
J46: Mode | K46: #N/A | M46: -500 | N46: 52 | O46: =N46/N$60 -> 0.052 | W46: Median | X46: 1237.1427 | AA46: -1500 | AB46: 7 | AC46: =AB46/AB$63 -> 0.007 | AJ46: Median | AK46: 2039.5921 | AO46: -1500 | AP46: 2 | AQ46: =AP46/AP$63 -> 0.002 | BB46: Mode | BC46: #N/A | BG46: -1000 | BH46: 5 | BI46: =BH46/BH$64 -> 0.005
J47: Standard Deviation | K47: 1122.0815 | M47: 0 | N47: 74 | O47: =N47/N$60 -> 0.074 | W47: Mode | X47: #N/A | AA47: -1000 | AB47: 17 | AC47: =AB47/AB$63 -> 0.017 | AJ47: Mode | AK47: #N/A | AO47: -1000 | AP47: 9 | AQ47: =AP47/AP$63 -> 0.009 | BB47: Standard Deviation | BC47: 1302.524 | BG47: -500 | BH47: 10 | BI47: =BH47/BH$64 -> 0.01
J48: Sample Variance | K48: 1259066.9 | M48: 500 | N48: 141 | O48: =N48/N$60 -> 0.141 | W48: Standard Deviation | X48: 1138.1297 | AA48: -500 | AB48: 29 | AC48: =AB48/AB$63 -> 0.029 | AJ48: Standard Deviation | AK48: 1343.1217 | AO48: -500 | AP48: 15 | AQ48: =AP48/AP$63 -> 0.015 | BB48: Sample Variance | BC48: 1696568.8 | BG48: 0 | BH48: 31 | BI48: =BH48/BH$64 -> 0.031
J49: Kurtosis | K49: 0.11283112 | M49: 1000 | N49: 167 | O49: =N49/N$60 -> 0.167 | W49: Sample Variance | X49: 1295339.2 | AA49: 0 | AB49: 68 | AC49: =AB49/AB$63 -> 0.068 | AJ49: Sample Variance | AK49: 1803976 | AO49: 0 | AP49: 27 | AQ49: =AP49/AP$63 -> 0.027 | BB49: Kurtosis | BC49: 0.30510425 | BG49: 500 | BH49: 61 | BI49: =BH49/BH$64 -> 0.061
J50: Skewness | K50: 0.15614818 | M50: 1500 | N50: 186 | O50: =N50/N$60 -> 0.186 | W50: Kurtosis | X50: 0.28686104 | AA50: 500 | AB50: 124 | AC50: =AB50/AB$63 -> 0.124 | AJ50: Kurtosis | AK50: -0.066922393 | AO50: 500 | AP50: 64 | AQ50: =AP50/AP$63 -> 0.064 | BB50: Skewness | BC50: 0.26672383 | BG50: 1000 | BH50: 86 | BI50: =BH50/BH$64 -> 0.086
J51: Range | K51: 6782.8246 | M51: 2000 | N51: 147 | O51: =N51/N$60 -> 0.147 | W51: Skewness | X51: 0.091478942 | AA51: 1000 | AB51: 163 | AC51: =AB51/AB$63 -> 0.163 | AJ51: Skewness | AK51: 0.11922926 | AO51: 1000 | AP51: 102 | AQ51: =AP51/AP$63 -> 0.102 | BB51: Range | BC51: 8799.2067 | BG51: 1500 | BH51: 116 | BI51: =BH51/BH$64 -> 0.116
J52: Minimum | K52: -2259.5724 | M52: 2500 | N52: 108 | O52: =N52/N$60 -> 0.108 | W52: Range | X52: 8184.0605 | AA52: 1500 | AB52: 188 | AC52: =AB52/AB$63 -> 0.188 | AJ52: Range | AK52: 8038.0105 | AO52: 1500 | AP52: 125 | AQ52: =AP52/AP$63 -> 0.125 | BB52: Minimum | BC52: -1562.2335 | BG52: 2000 | BH52: 148 | BI52: =BH52/BH$64 -> 0.148
J53: Maximum | K53: 4523.2521 | M53: 3000 | N53: 41 | O53: =N53/N$60 -> 0.041 | W53: Minimum | X53: -2686.5657 | AA53: 2000 | AB53: 145 | AC53: =AB53/AB$63 -> 0.145 | AJ53: Minimum | AK53: -1695.2392 | AO53: 2000 | AP53: 153 | AQ53: =AP53/AP$63 -> 0.153 | BB53: Maximum | BC53: 7236.9732 | BG53: 2500 | BH53: 182 | BI53: =BH53/BH$64 -> 0.182
J54: Sum | K54: 1113085.6 | M54: 3500 | N54: 33 | O54: =N54/N$60 -> 0.033 | W54: Maximum | X54: 5497.4948 | AA54: 2500 | AB54: 111 | AC54: =AB54/AB$63 -> 0.111 | AJ54: Maximum | AK54: 6342.7713 | AO54: 2500 | AP54: 146 | AQ54: =AP54/AP$63 -> 0.146 | BB54: Sum | BC54: 2134965 | BG54: 3000 | BH54: 134 | BI54: =BH54/BH$64 -> 0.134
J55: Count | K55: 1000 | M55: 4000 | N55: 17 | O55: =N55/N$60 -> 0.017 | W55: Sum | X55: 1266220.8 | AA55: 3000 | AB55: 82 | AC55: =AB55/AB$63 -> 0.082 | AJ55: Sum | AK55: 2051345.8 | AO55: 3000 | AP55: 120 | AQ55: =AP55/AP$63 -> 0.12 | BB55: Count | BC55: 1000 | BG55: 3500 | BH55: 93 | BI55: =BH55/BH$64 -> 0.093
M56: 4500 | N56: 5 | O56: =N56/N$60 -> 0.005 | W56: Count | X56: 1000 | AA56: 3500 | AB56: 36 | AC56: =AB56/AB$63 -> 0.036 | AJ56: Count | AK56: 1000 | AO56: 3500 | AP56: 92 | AQ56: =AP56/AP$63 -> 0.092 | BG56: 4000 | BH56: 51 | BI56: =BH56/BH$64 -> 0.051
M57: 5000 | N57: 2 | O57: =N57/N$60 -> 0.002 | AA57: 4000 | AB57: 15 | AC57: =AB57/AB$63 -> 0.015 | AO57: 4000 | AP57: 59 | AQ57: =AP57/AP$63 -> 0.059 | BG57: 4500 | BH57: 30 | BI57: =BH57/BH$64 -> 0.03
M58: 5500 | N58: 0 | O58: =N58/N$60 -> 0 | AA58: 4500 | AB58: 8 | AC58: =AB58/AB$63 -> 0.008 | AO58: 4500 | AP58: 43 | AQ58: =AP58/AP$63 -> 0.043 | BG58: 5000 | BH58: 27 | BI58: =BH58/BH$64 -> 0.027
M59: More | N59: 0 | AA59: 5000 | AB59: 1 | AC59: =AB59/AB$63 -> 0.001 | AO59: 5000 | AP59: 29 | AQ59: =AP59/AP$63 -> 0.029 | BG59: 6000 | BH59: 21 | BI59: =BH59/BH$64 -> 0.021
M60: Total Count | N60: 1000 | O60: =SUM(O42:O58) -> 0.999 | AA60: 5500 | AB60: 3 | AC60: =AB60/AB$63 -> 0.003 | AO60: 6000 | AP60: 9 | AQ60: =AP60/AP$63 -> 0.009 | BG60: 6500 | BH60: 2 | BI60: =BH60/BH$64 -> 0.002
AA61: 6000 | AB61: 0 | AC61: =AB61/AB$63 -> 0 | AO61: 6500 | AP61: 4 | AQ61: =AP61/AP$63 -> 0.004 | BG61: 7000 | BH61: 0 | BI61: =BH61/BH$64 -> 0
AA62: More | AB62: 0 | AO62: More | AP62: 0 | BG62: 7500 | BH62: 1 | BI62: =BH62/BH$64 -> 0.001
