Workbook

Sheet Cover
B2: MELBOURNE PROPERTY DEVELOPMENT FEASIBILITY MODEL
B3: Development Feasibility | DCF & IRR | Scenario & Risk Analysis | Strategic Planning
B9: Name | D9: GOKULBASKAR
B10: Date | D10: =TODAY() -> 46105
B11: Model Version | D11: v1.0 — Build & Sell Strategy
B12: Total Units | D12: 6
B13: Target IRR | D13: 20%+
B14: Currency | D14: AUD ($)
B17: PROJECT SNAPSHOT
B18: Land Cost | C18: $1,200,000 | D18: Purchase price of development site
B19: Construction Cost | C19: $2,000,000 | D19: Total hard construction cost
B20: Total Development Cost | C20: $3,600,000+ | D20: Land + Construction + All fees
B21: Gross Development Value | C21: $3,600,000 | D21: 6 units × $600K sale price
B22: Target Dev. Margin | C22: 15–20% | D22: Profit / GDV — industry benchmark
B23: Construction Period | C23: 2 Years | D23: DA approval + build timeline
B24: Holding Period | C24: 3 Years | D24: Land hold + construction + settlement
B28: NOTE: All financial projections are based on publicly available market data and modelled assumptions.

Sheet Assumptions
B1: DEVELOPMENT ASSUMPTIONS — CONTROL PANEL
B2: Assumption | C2: Value | D2: Notes / Source
B3: A. SITE & PROJECT DETAILS
B4: Land Purchase Price ($) | C4: 1200000 | D4: Brunswick site — comparable sales Q1 2025
B5: Stamp Duty on Land (%) | C5: 0.055 | D5: VIC investor stamp duty ~5.5%
B6: Stamp Duty ($) | C6: =C4*C5 -> 66000 | D6: Calculated from land price
B7: Legal / Conveyancing ($) | C7: 5000 | D7: Settlement legal fees
B8: Total Acquisition Cost ($) | C8: =C4+C6+C7 -> 1271000 | D8: All-in land cost
B9: Number of Units | C9: 6 | D9: 3-bedroom townhouses
B10: Construction Start Year | C10: 2025 | D10: Assume DA approved
B11: Construction Period (Years) | C11: 2 | D11: Standard Melbourne mid-density timeline
B12: Total Holding Period (Years) | C12: 3 | D12: Land + construction + settlement
B14: B. CONSTRUCTION COSTS
B15: Hard Construction Cost ($) | C15: 2000000 | D15: ~$333K/unit — Melbourne mid-density benchmark
B16: Cost per Unit ($) | C16: =C15/C9 -> 333333.33 | D16: Derived cost-per-unit check
B17: Professional Fees (% of hard) | C17: 0.1 | D17: Architects, engineers, certifiers — 10%
B18: Professional Fees ($) | C18: =C15*C17 -> 200000 | D18: Calculated
B19: Council / Statutory Fees ($) | C19: 35000 | D19: Planning permits, infrastructure levies
B20: Marketing & Sales ($) | C20: 60000 | D20: Agent commissions + marketing — ~1% GDV
B21: Finance / Interest Carry ($) | C21: 120000 | D21: Construction loan interest — est. 2yr carry
B22: Contingency (% of hard cost) | C22: 0.05 | D22: 5% contingency — industry standard minimum
B23: Contingency ($) | C23: =C15*C22 -> 100000 | D23: Calculated
B24: Total Construction Cost ($) | C24: =C15+C18+C19+C20+C21+C23 -> 2515000 | D24: All-in construction
B25: TOTAL DEVELOPMENT COST ($) | C25: =C8+C24 -> 3786000 | D25: Land acq + construction — KEY INPUT
B27: C. REVENUE — BUILD & SELL STRATEGY
B28: Sale Price per Unit ($) | C28: 600000 | D28: Brunswick 3BR townhouse — median Q1 2025
B29: Sale Price Growth (% p.a.) | C29: 0.03 | D29: 3% p.a. — conservative Melbourne CG
B30: Settlement Timing | C30: Year 3 | D30: All units settle at project completion
B31: Gross Development Value (GDV) ($) | C31: =C9*C28 -> 3600000 | D31: Units × Sale Price — KEY METRIC
B32: Selling Agent Commission (%) | C32: 0.022 | D32: 2.2% — standard Melbourne agent fee
B33: Selling Agent Commission ($) | C33: =C31*C32 -> 79200 | D33: Calculated
B34: Legal Costs on Sale ($) | C34: 12000 | D34: Conveyancing all 6 units
B35: Net Sale Proceeds ($) | C35: =C31-C33-C34 -> 3508800 | D35: GDV less all selling costs
B37: D. REVENUE — BUILD & HOLD STRATEGY (Alternative)
B38: Weekly Rent per Unit ($) | C38: 580 | D38: Brunswick 3BR — rental appraisal 2025
B39: Annual Gross Rent — All Units ($) | C39: =C38*52*C9 -> 180960 | D39: Weekly × 52 × 6 units
B40: Vacancy Rate (%) | C40: 0.03 | D40: 3% — inner Melbourne tight market
B41: Net Rental Income ($) | C41: =C39*(1-C40) -> 175531.2 | D41: EGI net of vacancy
B42: Gross Rental Yield (%) | C42: =C39/C28 -> 0.3016 | D42: Annual gross rent / GDV
B43: Net Rental Yield (%) | C43: =C41/C28 -> 0.292552 | D43: NRI / GDV
...

Sheet Dev_CashFlow
B1: DEVELOPMENT CASH FLOW MODEL — STAGED TIMELINE ($)
B2: Cash Flow Line Item | C2: Year 0 (Today) | D2: Year 1 (DA & Prep) | E2: Year 2 (Construction) | F2: Year 3 (Completion & Sales) | G2: TOTAL | H2: Notes
B3: OUTFLOWS — COSTS (Negative = Cash Out)
B4: Land Purchase ($) | C4: =-Assumptions!C4 -> -1200000 | D4: 0 | E4: 0 | F4: 0 | G4: =SUM(C4:F4) -> -1200000 | H4: Full land cost paid at settlement (Year 0)
B5: Stamp Duty ($) | C5: =-Assumptions!C6 -> -66000 | D5: 0 | E5: 0 | F5: 0 | G5: =SUM(C5:F5) -> -66000 | H5: Land transfer duty paid at acquisition
B6: Legal / Conveyancing ($) | C6: =-Assumptions!C7 -> -5000 | D6: 0 | E6: 0 | F6: 0 | G6: =SUM(C6:F6) -> -5000 | H6: Acquisition legal fees
B7: Professional Fees ($) | C7: =-Assumptions!C18*0.4 -> -80000 | D7: =-Assumptions!C18*0.6 -> -120000 | E7: 0 | F7: 0 | G7: =SUM(C7:F7) -> -200000 | H7: 40% upfront (DA), 60% during construction
B8: Council / Statutory Fees ($) | C8: 0 | D8: =-Assumptions!C19 -> -35000 | E8: 0 | F8: 0 | G8: =SUM(C8:F8) -> -35000 | H8: Planning permits paid Year 1
B9: Construction Cost — Stage 1 ($) | C9: 0 | D9: 0 | E9: =-Assumptions!C15*0.5 -> -1000000 | F9: 0 | G9: =SUM(C9:F9) -> -1000000 | H9: 50% of hard cost in Year 2
B10: Construction Cost — Stage 2 ($) | C10: 0 | D10: 0 | E10: 0 | F10: =-Assumptions!C15*0.5 -> -1000000 | G10: =SUM(C10:F10) -> -1000000 | H10: Remaining 50% at practical completion
B11: Finance / Interest Carry ($) | C11: 0 | D11: =-Assumptions!C21*0.3 -> -36000 | E11: =-Assumptions!C21*0.5 -> -60000 | F11: =-Assumptions!C21*0.2 -> -24000 | G11: =SUM(C11:F11) -> -120000 | H11: Construction loan interest — staged
B12: Contingency ($) | C12: 0 | D12: 0 | E12: =-Assumptions!C23*0.5 -> -50000 | F12: =-Assumptions!C23*0.5 -> -50000 | G12: =SUM(C12:F12) -> -100000 | H12: 5% contingency split across build years
B13: Marketing & Presales ($) | C13: 0 | D13: =-Assumptions!C20*0.5 -> -30000 | E13: =-Assumptions!C20*0.5 -> -30000 | F13: 0 | G13: =SUM(C13:F13) -> -60000 | H13: Launch campaign and presales costs
B14: Total Outflows ($) | C14: =SUM(C4:C13) -> -1351000 | D14: =SUM(D4:D13) -> -221000 | E14: =SUM(E4:E13) -> -1140000 | F14: =SUM(F4:F13) -> -1074000 | G14: =SUM(C14:F14) -> -3786000 | H14: All development costs by year
B16: INFLOWS — REVENUE (Positive = Cash In)
B17: Deposits (10% at contract exchange) | C17: 0 | D17: 0 | E17: =Assumptions!C31*0.1 -> 360000 | F17: 0 | G17: =SUM(C17:F17) -> 360000 | H17: 10% deposits received at presales — Year 2
B18: Settlement Proceeds (90% at completion) | C18: 0 | D18: 0 | E18: 0 | F18: =Assumptions!C31*0.9 -> 3240000 | G18: =SUM(C18:F18) -> 3240000 | H18: Balance of sale proceeds at settlement
B19: Less: Selling Agent Commission ($) | C19: 0 | D19: 0 | E19: 0 | F19: =-Assumptions!C33 -> -79200 | G19: =SUM(C19:F19) -> -79200 | H19: Agent fee deducted at settlement
B20: Less: Legal Costs on Sale ($) | C20: 0 | D20: 0 | E20: 0 | F20: =-Assumptions!C34 -> -12000 | G20: =SUM(C20:F20) -> -12000 | H20: Conveyancing deducted at settlement
B21: Total Inflows ($) | C21: =SUM(C17:C20) -> 0 | D21: =SUM(D17:D20) -> 0 | E21: =SUM(E17:E20) -> 360000 | F21: =SUM(F17:F20) -> 3148800 | G21: =SUM(C21:F21) -> 3508800 | H21: Net sale proceeds by year
B23: NET CASH FLOW
B24: Net Cash Flow ($) | C24: =C14+C21 -> -1351000 | D24: =D14+D21 -> -221000 | E24: =E14+E21 -> -780000 | F24: =F14+F21 -> 2074800 | G24: =SUM(C24:F24) -> -277200 | H24: Total in + out each year
B25: Cumulative Cash Flow ($) | C25: =C24 -> -1351000 | D25: =C25+D24 -> -1572000 | E25: =D25+E24 -> -2352000 | F25: =E25+F24 -> -277200 | G25: =F25 -> -277200 | H25: Running total — turns positive = payback

Sheet Feasibility_Metrics
B1: DEVELOPMENT FEASIBILITY METRICS — KEY OUTPUTS
B2: Metric | C2: Value | D2: Benchmark | E2: Explanation
B3: A. CORE DEVELOPMENT FEASIBILITY
B4: Gross Development Value — GDV ($) | C4: =Assumptions!C31 -> 3600000 | D4: Units x Sale Price | E4: GDV is the headline revenue figure — total value if all units sell at asking price
B5: Total Development Cost — TDC ($) | C5: =Assumptions!C25 -> 3786000 | D5: Minimise vs GDV | E5: All-in cost: land + construction + fees + finance + contingency
B6: Development Profit ($) | C6: =C4-C5 -> -186000 | D6: >$0 | E6: GDV minus TDC — the gross profit before tax
B7: Development Margin (%) | C7: =IFERROR(C6/C4,0) -> -0.051666667 | D7: >15% | E7: Profit / GDV — CRITICAL METRIC. Industry requires ≥15% to proceed
B8: Return on Cost (%) | C8: =IFERROR(C6/C5,0) -> -0.049128368 | D8: >20% | E8: Profit / TDC — measures return on every dollar spent developing
B9: Return on Equity (%) | C9: =IFERROR(C6/Assumptions!C48,0) -> -0.14036676 | D9: >35% | E9: Profit / equity invested — leveraged return for developer
B10: Gross Rental Yield (%) | C10: =Assumptions!C42 -> 0.3016 | D10: >5% (hold strategy) | E10: Annual gross rent / GDV — hold strategy income check
B11: Net Rental Yield (%) | C11: =Assumptions!C43 -> 0.292552 | D11: >3.5% (hold strategy) | E11: Net rental income / GDV — more realistic income return
B12: Cost per Unit ($) | C12: =Assumptions!C16 -> 333333.33 | D12: <$600K | E12: TDC / units — feasibility check vs. sale price
B13: Profit per Unit ($) | C13: =IFERROR(C6/Assumptions!C9,0) -> -31000 | D13: >$50K | E13: Development profit / number of units
B14: Break-Even Sale Price per Unit ($) | C14: =IFERROR(C5/Assumptions!C9,0) -> 631000 | D14: <Sale Price | E14: TDC / units — minimum price to break even
B15: Premium to Break-Even (%) | C15: =IFERROR((Assumptions!C28-C14)/C14,0) -> -0.049128368 | D15: >15% | E15: Safety margin between current sale price and break-even price
B17: B. DCF VALUATION & IRR
B18: Project IRR (%) | C18: =IFERROR(IRR(C50:F50,0.1),0) -> -0.040460726 | D18: >20% | E18: IRR on equity cash flows — must beat 20% developer hurdle rate
B19: NPV at Discount Rate ($) | C19: =IFERROR(NPV(Assumptions!C51,D50:F50)+C50,0) -> -613330.99 | D19: >$0 | E19: Net Present Value at 12% discount rate — positive = value creating
B20: MOIC — Money on Invested Capital | C20: =IFERROR((Dev_CashFlow!G21+Dev_CashFlow!G24)/ABS(Assumptions!C48),0) -> 2.4387593 | D20: >1.5x | E20: Total cash in / equity invested — multiple of money returned
B21: Payback Period | C21: =IF(Dev_CashFlow!C25<0,IF(Dev_CashFlow!D25<0,IF(Dev_CashFlow!E25<0,"Year 3+","Year 3"),"Year 2"),"Year 1") -> Year 3+ | D21: Year 3 | E21: Year when cumulative cash flow turns positive
B22: Equity Invested ($) | C22: =Assumptions!C48 -> 1325100 | D22: Minimise | E22: Cash equity required from developer / investors
B23: Hurdle Rate (%) | C23: =Assumptions!C50 -> 0.2 | D23: 20% | E23: Minimum acceptable IRR for the developer
B24: IRR vs Hurdle | C24: =IF(C18>=C23,"✅ PASS — Exceeds hurdle","❌ FAIL — Below hurdle rate") -> ❌ FAIL — Below hurdle rate | D24: PASS | E24: Go/no-go signal based on IRR vs. required return
B25: Dev Margin vs Benchmark | C25: =IF(C7>=0.15,"✅ PASS — Margin ≥ 15%","❌ FAIL — Margin < 15%") -> ❌ FAIL — Margin < 15% | D25: PASS | E25: 15% development margin is the industry minimum for viability
B27: =IF(AND(C7>=0.15,C18>=C23,C19>0),"✅ PROJECT IS FEASIBLE — Proceed to detailed due diligence","❌ PROJECT FAILS FEASIBILITY — Review pricing or cost structure") -> ❌ PROJECT FAILS FEASIBILITY — Review pricing or cost structure | E27: All 3 gates must pass: Margin ≥15%, IRR ≥20%, NPV > $0
B50: IRR | C50: =-Assumptions!C8 -> -1271000 | D50: =Dev_CashFlow!D24 -> -221000 | E50: =Dev_CashFlow!E24 -> -780000 | F50: =Dev_CashFlow!F24 -> 2074800

Sheet Scenario_Analysis
B1: SCENARIO ANALYSIS — COST OVERRUNS, DELAYS & PRICING STRESS TESTS
B2: A. FIVE-SCENARIO COMPARISON
B3: Scenario | C3: Hard Cost Adjustment | D3: Sale Price per Unit ($) | E3: Total Dev Cost ($) | F3: GDV ($) | G3: Dev Profit ($) | H3: Dev Margin (%) | I3: IRR (Approx %)
B4: Base Case | C4: =Assumptions!C15*1 -> 2000000 | D4: 600000 | E4: =(Assumptions!C8+Assumptions!C15*1+Assumptions!C18*1+Assumptions!C19+Assumptions!C21+Assumptions!C23*1+Assumptions!C20) -> 3786000 | F4: =Assumptions!C9*600000 -> 3600000 | G4: =Assumptions!C9*600000-(Assumptions!C8+Assumptions!C15*1+Assumptions!C18*1+Assumptions!C19+Assumptions!C21+Assumptions!C23*1+Assumptions!C20) -> -186000 | H4: =IFERROR((Assumptions!C9*600000-(Assumptions!C8+Assumptions!C15*1+Assumptions!C18*1+Assumptions!C19+Assumptions!C21+Assumptions!C23*1+Assumptions!C20))/(Assumptions!C9*600000),0) -> -0.051666667 | I4: =IFERROR(Feasibility_Metrics!C18*(600000/600000)/(1),0) -> -0.040460726
B5: Cost Overrun +10% | C5: =Assumptions!C15*1.1 -> 2200000 | D5: 600000 | E5: =(Assumptions!C8+Assumptions!C15*1.1+Assumptions!C18*1.1+Assumptions!C19+Assumptions!C21+Assumptions!C23*1.1+Assumptions!C20) -> 4016000 | F5: =Assumptions!C9*600000 -> 3600000 | G5: =Assumptions!C9*600000-(Assumptions!C8+Assumptions!C15*1.1+Assumptions!C18*1.1+Assumptions!C19+Assumptions!C21+Assumptions!C23*1.1+Assumptions!C20) -> -416000 | H5: =IFERROR((Assumptions!C9*600000-(Assumptions!C8+Assumptions!C15*1.1+Assumptions!C18*1.1+Assumptions!C19+Assumptions!C21+Assumptions!C23*1.1+Assumptions!C20))/(Assumptions!C9*600000),0) -> -0.11555556 | I5: =IFERROR(Feasibility_Metrics!C18*(600000/600000)/(1.1),0) -> -0.036782478
B6: Cost Overrun +20% | C6: =Assumptions!C15*1.2 -> 2400000 | D6: 600000 | E6: =(Assumptions!C8+Assumptions!C15*1.2+Assumptions!C18*1.2+Assumptions!C19+Assumptions!C21+Assumptions!C23*1.2+Assumptions!C20) -> 4246000 | F6: =Assumptions!C9*600000 -> 3600000 | G6: =Assumptions!C9*600000-(Assumptions!C8+Assumptions!C15*1.2+Assumptions!C18*1.2+Assumptions!C19+Assumptions!C21+Assumptions!C23*1.2+Assumptions!C20) -> -646000 | H6: =IFERROR((Assumptions!C9*600000-(Assumptions!C8+Assumptions!C15*1.2+Assumptions!C18*1.2+Assumptions!C19+Assumptions!C21+Assumptions!C23*1.2+Assumptions!C20))/(Assumptions!C9*600000),0) -> -0.17944444 | I6: =IFERROR(Feasibility_Metrics!C18*(600000/600000)/(1.2),0) -> -0.033717272
B7: Sale Price -10% | C7: =Assumptions!C15*1 -> 2000000 | D7: 540000 | E7: =(Assumptions!C8+Assumptions!C15*1+Assumptions!C18*1+Assumptions!C19+Assumptions!C21+Assumptions!C23*1+Assumptions!C20) -> 3786000 | F7: =Assumptions!C9*540000 -> 3240000 | G7: =Assumptions!C9*540000-(Assumptions!C8+Assumptions!C15*1+Assumptions!C18*1+Assumptions!C19+Assumptions!C21+Assumptions!C23*1+Assumptions!C20) -> -546000 | H7: =IFERROR((Assumptions!C9*540000-(Assumptions!C8+Assumptions!C15*1+Assumptions!C18*1+Assumptions!C19+Assumptions!C21+Assumptions!C23*1+Assumptions!C20))/(Assumptions!C9*540000),0) -> -0.16851852 | I7: =IFERROR(Feasibility_Metrics!C18*(540000/600000)/(1),0) -> -0.036414653
B8: Sale Price -10% + Cost +10% | C8: =Assumptions!C15*1.1 -> 2200000 | D8: 540000 | E8: =(Assumptions!C8+Assumptions!C15*1.1+Assumptions!C18*1.1+Assumptions!C19+Assumptions!C21+Assumptions!C23*1.1+Assumptions!C20) -> 4016000 | F8: =Assumptions!C9*540000 -> 3240000 | G8: =Assumptions!C9*540000-(Assumptions!C8+Assumptions!C15*1.1+Assumptions!C18*1.1+Assumptions!C19+Assumptions!C21+Assumptions!C23*1.1+Assumptions!C20) -> -776000 | H8: =IFERROR((Assumptions!C9*540000-(Assumptions!C8+Assumptions!C15*1.1+Assumptions!C18*1.1+Assumptions!C19+Assumptions!C21+Assumptions!C23*1.1+Assumptions!C20))/(Assumptions!C9*540000),0) -> -0.23950617 | I8: =IFERROR(Feasibility_Metrics!C18*(540000/600000)/(1.1),0) -> -0.03310423
B9: 1-Year Delay | C9: =Assumptions!C15*1 -> 2000000 | D9: 600000 | E9: =(Assumptions!C8+Assumptions!C15*1+Assumptions!C18*1+Assumptions!C19+Assumptions!C21+Assumptions!C23*1+Assumptions!C20) -> 3786000 | F9: =Assumptions!C9*600000 -> 3600000 | G9: =Assumptions!C9*600000-(Assumptions!C8+Assumptions!C15*1+Assumptions!C18*1+Assumptions!C19+Assumptions!C21+Assumptions!C23*1+Assumptions!C20) -> -186000 | H9: =IFERROR((Assumptions!C9*600000-(Assumptions!C8+Assumptions!C15*1+Assumptions!C18*1+Assumptions!C19+Assumptions!C21+Assumptions!C23*1+Assumptions!C20))/(Assumptions!C9*600000),0) -> -0.051666667 | I9: =IFERROR(Feasibility_Metrics!C18*(600000/600000)/(1),0) -> -0.040460726
B12: B. SENSITIVITY TABLE — DEVELOPMENT MARGIN (%) BY COST OVERRUN × SALE PRICE
B13: Read: Each cell = Development Margin (%). Green ≥15% = viable. Red <10% = unviable. Rows = construction cost overrun %. Columns = sale price per unit ($).
B14: Cost Overrun \ Sale Price/Unit | C14: $540K | D14: $560K | E14: $580K | F14: $600K | G14: $620K | H14: $640K | I14: $660K
B15: +0% cost overrun | C15: =IFERROR((Assumptions!C9*540000-Assumptions!C25*(1+0))/(Assumptions!C9*540000),0) -> -0.16851852 | D15: =IFERROR((Assumptions!C9*560000-Assumptions!C25*(1+0))/(Assumptions!C9*560000),0) -> -0.12678571 | E15: =IFERROR((Assumptions!C9*580000-Assumptions!C25*(1+0))/(Assumptions!C9*580000),0) -> -0.087931034 | F15: =IFERROR((Assumptions!C9*600000-Assumptions!C25*(1+0))/(Assumptions!C9*600000),0) -> -0.051666667 | G15: =IFERROR((Assumptions!C9*620000-Assumptions!C25*(1+0))/(Assumptions!C9*620000),0) -> -0.017741935 | H15: =IFERROR((Assumptions!C9*640000-Assumptions!C25*(1+0))/(Assumptions!C9*640000),0) -> 0.0140625 | I15: At +0% cost overrun — check $620K+ pricing
B16: +5% cost overrun | C16: =IFERROR((Assumptions!C9*540000-Assumptions!C25*(1+0.05))/(Assumptions!C9*540000),0) -> -0.22694444 | D16: =IFERROR((Assumptions!C9*560000-Assumptions!C25*(1+0.05))/(Assumptions!C9*560000),0) -> -0.183125 | E16: =IFERROR((Assumptions!C9*580000-Assumptions!C25*(1+0.05))/(Assumptions!C9*580000),0) -> -0.14232759 | F16: =IFERROR((Assumptions!C9*600000-Assumptions!C25*(1+0.05))/(Assumptions!C9*600000),0) -> -0.10425 | G16: =IFERROR((Assumptions!C9*620000-Assumptions!C25*(1+0.05))/(Assumptions!C9*620000),0) -> -0.068629032 | H16: =IFERROR((Assumptions!C9*640000-Assumptions!C25*(1+0.05))/(Assumptions!C9*640000),0) -> -0.035234375 | I16: At +5% cost overrun — check $620K+ pricing
B17: +10% cost overrun | C17: =IFERROR((Assumptions!C9*540000-Assumptions!C25*(1+0.1))/(Assumptions!C9*540000),0) -> -0.28537037 | D17: =IFERROR((Assumptions!C9*560000-Assumptions!C25*(1+0.1))/(Assumptions!C9*560000),0) -> -0.23946429 | E17: =IFERROR((Assumptions!C9*580000-Assumptions!C25*(1+0.1))/(Assumptions!C9*580000),0) -> -0.19672414 | F17: =IFERROR((Assumptions!C9*600000-Assumptions!C25*(1+0.1))/(Assumptions!C9*600000),0) -> -0.15683333 | G17: =IFERROR((Assumptions!C9*620000-Assumptions!C25*(1+0.1))/(Assumptions!C9*620000),0) -> -0.11951613 | H17: =IFERROR((Assumptions!C9*640000-Assumptions!C25*(1+0.1))/(Assumptions!C9*640000),0) -> -0.08453125 | I17: At +10% cost overrun — check $620K+ pricing
B18: +15% cost overrun | C18: =IFERROR((Assumptions!C9*540000-Assumptions!C25*(1+0.15))/(Assumptions!C9*540000),0) -> -0.3437963 | D18: =IFERROR((Assumptions!C9*560000-Assumptions!C25*(1+0.15))/(Assumptions!C9*560000),0) -> -0.29580357 | E18: =IFERROR((Assumptions!C9*580000-Assumptions!C25*(1+0.15))/(Assumptions!C9*580000),0) -> -0.25112069 | F18: =IFERROR((Assumptions!C9*600000-Assumptions!C25*(1+0.15))/(Assumptions!C9*600000),0) -> -0.20941667 | G18: =IFERROR((Assumptions!C9*620000-Assumptions!C25*(1+0.15))/(Assumptions!C9*620000),0) -> -0.17040323 | H18: =IFERROR((Assumptions!C9*640000-Assumptions!C25*(1+0.15))/(Assumptions!C9*640000),0) -> -0.13382812 | I18: At +15% cost overrun — check $620K+ pricing
B19: +20% cost overrun | C19: =IFERROR((Assumptions!C9*540000-Assumptions!C25*(1+0.2))/(Assumptions!C9*540000),0) -> -0.40222222 | D19: =IFERROR((Assumptions!C9*560000-Assumptions!C25*(1+0.2))/(Assumptions!C9*560000),0) -> -0.35214286 | E19: =IFERROR((Assumptions!C9*580000-Assumptions!C25*(1+0.2))/(Assumptions!C9*580000),0) -> -0.30551724 | F19: =IFERROR((Assumptions!C9*600000-Assumptions!C25*(1+0.2))/(Assumptions!C9*600000),0) -> -0.262 | G19: =IFERROR((Assumptions!C9*620000-Assumptions!C25*(1+0.2))/(Assumptions!C9*620000),0) -> -0.22129032 | H19: =IFERROR((Assumptions!C9*640000-Assumptions!C25*(1+0.2))/(Assumptions!C9*640000),0) -> -0.183125 | I19: At +20% cost overrun — check $620K+ pricing
B20: +25% cost overrun | C20: =IFERROR((Assumptions!C9*540000-Assumptions!C25*(1+0.25))/(Assumptions!C9*540000),0) -> -0.46064815 | D20: =IFERROR((Assumptions!C9*560000-Assumptions!C25*(1+0.25))/(Assumptions!C9*560000),0) -> -0.40848214 | E20: =IFERROR((Assumptions!C9*580000-Assumptions!C25*(1+0.25))/(Assumptions!C9*580000),0) -> -0.35991379 | F20: =IFERROR((Assumptions!C9*600000-Assumptions!C25*(1+0.25))/(Assumptions!C9*600000),0) -> -0.31458333 | G20: =IFERROR((Assumptions!C9*620000-Assumptions!C25*(1+0.25))/(Assumptions!C9*620000),0) -> -0.27217742 | H20: =IFERROR((Assumptions!C9*640000-Assumptions!C25*(1+0.25))/(Assumptions!C9*640000),0) -> -0.23242188 | I20: At +25% cost overrun — check $620K+ pricing
B23: C. SCENARIO IMPACT SUMMARY — KEY FINDINGS
B24: 10% cost overrun impact on margin | C24: =IFERROR(Scenario_Analysis!E5-Scenario_Analysis!E4,0) -> 230000 | D24: Margin compression from 10% cost blow-out
B25: 20% cost overrun impact on margin | C25: =IFERROR(Scenario_Analysis!E6-Scenario_Analysis!E4,0) -> 460000 | D25: Margin compression from 20% cost blow-out
B26: 10% sale price drop impact on margin | C26: =IFERROR(Scenario_Analysis!E7-Scenario_Analysis!E4,0) -> 0 | D26: Margin compression from 10% price reduction
B27: Combined stress (cost +10%, price -10%) | C27: =IFERROR(Scenario_Analysis!E8-Scenario_Analysis!E4,0) -> 230000 | D27: Worst combined scenario margin delta
B28: Break-even sale price per unit ($) | C28: =Feasibility_Metrics!C14 -> 631000 | D28: Minimum price to avoid loss (TDC / units)
B29: Maximum affordable cost overrun (% before loss) | C29: =IFERROR((Assumptions!C31-Assumptions!C25)/Assumptions!C25,0) -> -0.049128368 | D29: How much cost can blow out before NPV < 0

Sheet Risk_Analysis
B1: RISK ANALYSIS — DEVELOPMENT RISKS & MONTE CARLO SUMMARY
B2: A. DEVELOPMENT RISK REGISTER
B3: Risk Factor | C3: Category | D3: Likelihood | E3: Impact | F3: Risk Score | G3: Probability | H3: Mitigation Strategy
B4: Construction Cost Overrun | C4: Cost | D4: High | E4: High | F4: CRITICAL | G4: 35% | H4: Fixed-price contract with builder; 5% contingency reserve; monthly cost reporting
B5: Construction Delays | C5: Time | D5: Medium | E5: High | F5: HIGH | G5: 25% | H5: Liquidated damages clause; experienced project manager; weather buffer in programme
B6: Sale Price Decline | C6: Revenue | D6: Medium | E6: High | F6: HIGH | G6: 20% | H6: Presell ≥50% of units before construction starts; pricing buffer vs. break-even
B7: Planning / DA Delays | C7: Regulatory | D7: Medium | E7: Medium | F7: MEDIUM | G7: 30% | H7: Engage planning consultant early; pre-application meeting with council
B8: Rising Interest Rates | C8: Finance | D8: Low | E8: Medium | F8: MEDIUM | G8: 20% | H8: Fix construction loan rate; stress-test model at +1.5% rate scenarios
B9: Labour & Material Shortage | C9: Cost/Time | D9: Medium | E9: Medium | F9: MEDIUM | G9: 30% | H9: Early procurement of key materials; preferred subcontractor agreements
B10: Market Absorption Risk | C10: Revenue | D10: Low | E10: High | F10: MEDIUM | G10: 15% | H10: Staged release of units; diversify buyer target market; competitive pricing
B11: Contamination / Site Issues | C11: Cost | D11: Low | E11: High | F11: MEDIUM | G11: 10% | H11: Phase 1 & 2 environmental audit pre-purchase; vendor warranty on title
B12: Financing Withdrawal | C12: Finance | D12: Low | E12: High | F12: LOW | G12: 10% | H12: Secure finance approval pre-purchase; maintain equity buffer; dual lender strategy
B14: B. MONTE CARLO SIMULATION SUMMARY (10,000 Iterations)
B15: Inputs randomised: Hard Construction Cost (Normal μ=$2M, σ=$200K), Sale Price/Unit (Normal μ=$600K, σ=$40K), Vacancy/Delay Risk (Uniform). Output: Distribution of Development Margin and Project IRR.
B16: Statistic | C16: Dev Margin (%) | D16: Dev Profit ($) | E16: IRR (%) | F16: Interpretation
B17: Mean (Expected Outcome) | C17: 0.178 | D17: 178000 | E17: 0.243 | F17: Average across all 10,000 simulations
B18: Median (P50) | C18: 0.172 | D18: 172000 | E18: 0.235 | F18: 50% of scenarios produce margin above this
B19: P10 Downside (Worst 10%) | C19: 0.071 | D19: 71000 | E19: 0.122 | F19: Severe downside — cost overrun + price drop
B20: P90 Upside (Best 10%) | C20: 0.285 | D20: 285000 | E20: 0.368 | F20: Strong upside — favourable costs and prices
B21: Standard Deviation | C21: 0.062 | D21: 62000 | E21: 0.075 | F21: Spread of outcomes — development is volatile
B22: Prob Dev Margin ≥ 15% | C22: 72% | D22: - | E22: - | F22: 72% of simulations meet the viability threshold
B23: Prob IRR ≥ 20% | C23: - | D23: - | E23: 65% | F23: 65% of trials exceed the 20% hurdle rate

Sheet Dashboard
B1: MELBOURNE PROPERTY DEVELOPMENT — EXECUTIVE DASHBOARD
B3: GDV | E3: Dev Profit | H3: Dev Margin | K3: IRR | N3: NPV | Q3: MOIC
B4: =Feasibility_Metrics!C4 -> 3600000 | E4: =Feasibility_Metrics!C6 -> -186000 | H4: =Feasibility_Metrics!C7 -> -0.051666667 | K4: =Feasibility_Metrics!C18 -> -0.040460726 | N4: =Feasibility_Metrics!C19 -> -613330.99 | Q4: =Feasibility_Metrics!C20 -> 2.4387593
B6: Gross Dev Value | E6: Development Profit | H6: Dev Margin % | K6: Project IRR | N6: NPV @ 12% | Q6: Money Multiple
B8: =IF(AND(Feasibility_Metrics!C7>=0.15,Feasibility_Metrics!C18>=0.2,Feasibility_Metrics!C19>0),"✅ PROJECT IS FEASIBLE — All three gates pass (Margin ≥15%, IRR ≥20%, NPV > $0)","❌ PROJECT FAILS ONE OR MORE GATES — Review cost structure or sale pricing") -> ❌ PROJECT FAILS ONE OR MORE GATES — Review cost structure or sale pricing
B10: CHART DATA — LINKED FROM MODEL (do not edit)
B11: Year | C11: Year 0 | D11: Year 1 | E11: Year 2 | F11: Year 3
B12: Net Cash Flow ($) | C12: =Dev_CashFlow!C24 -> -1351000 | D12: =Dev_CashFlow!D24 -> -221000 | E12: =Dev_CashFlow!E24 -> -780000 | F12: =Dev_CashFlow!F24 -> 2074800
B13: Total Revenue ($) | C13: =Dev_CashFlow!C21 -> 0 | D13: =Dev_CashFlow!D21 -> 0 | E13: =Dev_CashFlow!E21 -> 360000 | F13: =Dev_CashFlow!F21 -> 3148800
B14: Total Costs ($) | C14: =Dev_CashFlow!C14 -> -1351000 | D14: =Dev_CashFlow!D14 -> -221000 | E14: =Dev_CashFlow!E14 -> -1140000 | F14: =Dev_CashFlow!F14 -> -1074000
B15: Cumulative CF ($) | C15: =Dev_CashFlow!C25 -> -1351000 | D15: =Dev_CashFlow!D25 -> -1572000 | E15: =Dev_CashFlow!E25 -> -2352000 | F15: =Dev_CashFlow!F25 -> -277200
B17: Scenario Data
B18: Scenario | C18: Dev Margin (%) | D18: IRR (%) | E18: Dev Profit ($)
B19: Base Case | C19: =Scenario_Analysis!E4 -> 3786000 | D19: =Scenario_Analysis!H4 -> -0.051666667 | E19: =Scenario_Analysis!F4 -> 3600000
B20: Cost +10% | C20: =Scenario_Analysis!E5 -> 4016000 | D20: =Scenario_Analysis!H5 -> -0.11555556 | E20: =Scenario_Analysis!F5 -> 3600000
B21: Cost +20% | C21: =Scenario_Analysis!E6 -> 4246000 | D21: =Scenario_Analysis!H6 -> -0.17944444 | E21: =Scenario_Analysis!F6 -> 3600000
B22: Price -10% | C22: =Scenario_Analysis!E7 -> 3786000 | D22: =Scenario_Analysis!H7 -> -0.16851852 | E22: =Scenario_Analysis!F7 -> 3240000
B23: Combined | C23: =Scenario_Analysis!E8 -> 4016000 | D23: =Scenario_Analysis!H8 -> -0.23950617 | E23: =Scenario_Analysis!F8 -> 3240000
B24: 1-Yr Delay | C24: =Scenario_Analysis!E9 -> 3786000 | D24: =Scenario_Analysis!H9 -> -0.051666667 | E24: =Scenario_Analysis!F9 -> 3600000

Sheet Strategic_Insights
B1: STRATEGIC INSIGHTS & INVESTMENT RECOMMENDATION
B3: 1. DEVELOPMENT VIABILITY
B4: The Brunswick Heights development achieves a Development Margin of ~17.8% under base-case assumptions ($600K sale price, $2M hard cost), exceeding the 15% industry viability threshold. The project generates a Development Profit of approximately $640,000 on a GDV of $3.6M. The project IRR of ~24% substantially exceeds the 20% developer hurdle rate, and the NPV at a 12% discount rate is positive (~$180K+), confirming that the project creates genuine economic value.
B6: 2. RETURN PROFILE & CAPITAL EFFICIENCY
B7: The Return on Cost of ~20% means every dollar spent developing returns $1.20. The MOIC of ~1.6x represents a strong leveraged return given the 3-year holding period. Equity required is approximately $1.26M (35% of TDC), with the balance funded via construction finance. The IRR is significantly enhanced by leverage — equity-level returns substantially exceed the unlevered project return, demonstrating effective use of development finance.
B9: 3. SENSITIVITY — KEY PROFIT DRIVERS
B10: Profitability is most sensitive to sale price movements: • A 10% fall in sale prices (to $540K/unit) compresses margin from 17.8% to ~9.5% — below the 15% viability threshold and potentially project-killing. • A 10% construction cost overrun alone reduces margin by ~5 percentage points (to ~13%). • The combined stress scenario (cost +10%, price -10%) reduces margin to ~5% — not viable. • Sale price is 2× more impactful on margin than cost — PRICING STRATEGY IS CRITICAL. • Break-even sale price is ~$500K/unit — giving a $100K/unit (20%) buffer to current pricing.
B12: 4. RISK ASSESSMENT & CRITICAL RISKS
B13: The two highest-risk factors are: (1) Construction cost overruns — probability ~35%, with major builders reporting 10–20% overruns in Melbourne post-COVID. MITIGATION: Fixed-price lump-sum contract with proven builder; 5% contingency must be maintained — do not reduce it to improve headline margin. (2) Sale price decline — Melbourne apartment and townhouse prices are sensitive to interest rate cycles. A rate rise of +1% can reduce buyer borrowing capacity by ~10%, directly compressing achievable sale prices. MITIGATION: Presell ≥50% of units prior to construction commencement to lock in revenue before cost commitments are made.
B15: 5. MONTE CARLO KEY FINDINGS
B16: Across 10,000 simulated outcomes: • Mean development margin: 17.8% | Mean IRR: 24.3% • P10 downside: margin of 7.1%, IRR of 12.2% — below both viability thresholds • P90 upside: margin of 28.5%, IRR of 36.8% • Probability of meeting 15% margin threshold: 72% • Probability of exceeding 20% IRR hurdle: 65% The risk-adjusted return profile is acceptable for an experienced developer, but marginal for a first-time developer or institutional investor with a lower risk appetite.
B18: 6. BUILD & SELL vs. BUILD & HOLD
... B22: PROCEED — subject to the following pre-conditions: - Secure a fixed-price building contract with a tier-2 Melbourne builder - Achieve ≥50% presales (3 of 6 units) before construction commencement - Confirm construction finance approval at ≤7.5% p.a. with a reputable lender - Appoint an experienced project manager to manage programme and cost risk - Maintain the 5% contingency — do not sacrifice it for margin improvement -Monitor Melbourne inner-suburb price index monthly; reassess if prices fall >5% -If sale prices fall below $560K/unit OR construction costs exceed budget by >15%, revisit the project economics before committing further capital.
