Workbook

Sheet Sheet1
A1: INTRODUCTION: Purpose: Optimize an 8-asset investment portfolio to maximize returns while managing risk. The task uses real ASX stock data to demonstrate portfolio modelling techniques. Approach: Used historical monthly returns (Jan 2021 – Jan 2025) for 8 selected stocks and formulated two optimisation models – a Linear Program (LP) and an Integer Linear Program (ILP). The LP allows fractional investment in each asset, while the ILP restricts to choosing a subset of assets. Tools: Microsoft Excel and Solver were used to implement the models. Constraints were derived from diversification and risk requirements. Solver’s Simplex LP algorithm (and branch-and-bound for ILP) identified the optimal allocations. Sensitivity analysis was conducted on the LP model to interpret constraint impacts.

Sheet 1.a Compute rate of return
B2: Using the closing stock prices of 49 monthly data calculate the monthly rate of returns for 48 months commencing from 1st of January 2021 to 1st of January 2025
B3: Table 1.a.1 | E3: Healthcare | M3: Technology | U3: Communication services | AC3: Financial Services
B4: monthly return of 1.Pro Medicus Limited (ASX.PME) | F4: Monthly retun of 2.Paragon Care Limited (ASX:PGC) | J4: 3.monthly return of Xero Limited (ASX:XRO) | N4: Monthly return of 4.COSOL Limited (ASX:COS) | R4: 5.monthly retun of Telstra Group Limited (ASX:TLS) | V4: 6. Monthly return of TPG Telecom Limited (ASX:TPG) | Z4: monthly return of 7.Commonwealth Bank (ASX:CBA) | AD4: Monthly return of 8.Suncorp Group Limited (ASX:SUN)
B5: {=_xlfn.STOCKHISTORY("XASX:PME","01-01-2021","01-01-2025",2,1,0,1)} -> Date | C5: Close | D5: monthly rate of return | F5: {=_xlfn.STOCKHISTORY("XASX:PGC","01-01-2021","01-01-2025",2,1,0,1)} -> Date | G5: Close | H5: monthly rate of return | J5: {=_xlfn.STOCKHISTORY("XASX:XRO","01-01-2021","01-01-2025",2,1,0,1)} -> Date | K5: Close | L5: monthly rate of return | N5: {=_xlfn.STOCKHISTORY("XASX:COS","01-01-2021","01-01-2025",2,1,0,1)} -> Date | O5: Close | P5: monthly rate of return | R5: {=_xlfn.STOCKHISTORY("XASX:TLS","01-01-2021","01-01-2025",2,1,0,1)} -> Date | S5: Close | T5: monthly rate of return | V5: {=_xlfn.STOCKHISTORY("XASX:TPG","01-01-2021","01-01-2025",2,1,0,1)} -> Date | W5: Close | X5: monthly rate of return | Z5: {=_xlfn.STOCKHISTORY("XASX:CBA","01-01-2021","01-01-2025",2,1,0,1)} -> Date | AA5: Close | AB5: monthly rate of return | AD5: {=_xlfn.STOCKHISTORY("XASX:SUN","01-01-2021","01-01-2025",2,1,0,1)} -> Date | AE5: Close | AF5: monthly rate of return | AK5: Symbol | AL5: Company | AM5: Category | AN5: Category code | AO5: Category code for chosen assests
A6: 0 | B6: 44197 | C6: 42.84 | F6: 44197 | G6: 0.24 | J6: 44197 | K6: 129.89 | N6: 44197 | O6: 0.65 | R6: 44197 | S6: 3.12 | V6: 44197 | W6: 7.4 | Z6: 44197 | AA6: 83.51 | AD6: 44197 | AE6: 10.0009 | AK6: (ASX:PME) | AL6: Pro Medicus Limited | AM6: Healthcare | AN6: S1 | AO6: S11
A7: 1 | B7: 44228 | C7: 44.35 | D7: =(C7-C6)/C6 -> 0.035247432 | F7: 44228 | G7: 0.27 | H7: =(G7-G6)/G6 -> 0.125 | J7: 44228 | K7: 118.43 | L7: =(K7-K6)/K6 -> -0.088228501 | N7: 44228 | O7: 0.65 | P7: =(O7-O6)/O6 -> 0 | R7: 44228 | S7: 3.08 | T7: =(S7-S6)/S6 -> -0.012820513 | V7: 44228 | W7: 6.8 | X7: =(W7-W6)/W6 -> -0.081081081 | Z7: 44228 | AA7: 81.56 | AB7: =(AA7-AA6)/AA6 -> -0.023350497 | AD7: 44228 | AE7: 9.862 | AF7: =(AE7-AE6)/AE6 -> -0.01388875 | AK7: (ASX:PGC) | AL7: Paragon Care Limited | AO7: S12
A8: 2 | B8: 44256 | C8: 41.33 | D8: =(C8-C7)/C7 -> -0.068094701 | F8: 44256 | G8: 0.24 | H8: =(G8-G7)/G7 -> -0.11111111 | J8: 44256 | K8: 126.53 | L8: =(K8-K7)/K7 -> 0.068394832 | N8: 44256 | O8: 0.75 | P8: =(O8-O7)/O7 -> 0.15384615 | R8: 44256 | S8: 3.4 | T8: =(S8-S7)/S7 -> 0.1038961 | V8: 44256 | W8: 6.33 | X8: =(W8-W7)/W7 -> -0.069117647 | Z8: 44256 | AA8: 86.1 | AB8: =(AA8-AA7)/AA7 -> 0.055664541 | AD8: 44256 | AE8: 9.8223 | AF8: =(AE8-AE7)/AE7 -> -0.0040255526 | AK8: (ASX:XRO) | AL8: Xero Limited | AM8: Technology | AN8: S2 | AO8: S21
A9: 3 | B9: 44287 | C9: 47.21 | D9: =(C9-C8)/C8 -> 0.14226954 | F9: 44287 | G9: 0.225 | H9: =(G9-G8)/G8 -> -0.0625 | J9: 44287 | K9: 141.56 | L9: =(K9-K8)/K8 -> 0.11878606 | N9: 44287 | O9: 0.74 | P9: =(O9-O8)/O8 -> -0.013333333 | R9: 44287 | S9: 3.39 | T9: =(S9-S8)/S8 -> -0.0029411765 | V9: 44287 | W9: 5.51 | X9: =(W9-W8)/W8 -> -0.12954186 | Z9: 44287 | AA9: 89.04 | AB9: =(AA9-AA8)/AA8 -> 0.034146341 | AD9: 44287 | AE9: 10.4275 | AF9: =(AE9-AE8)/AE8 -> 0.061614897 | AK9: (ASX:COS) | AL9: COSOL Limited | AO9: S22
A10: 4 | B10: 44317 | C10: 46.11 | D10: =(C10-C9)/C9 -> -0.023300148 | F10: 44317 | G10: 0.265 | H10: =(G10-G9)/G9 -> 0.17777778 | J10: 44317 | K10: 132.65 | L10: =(K10-K9)/K9 -> -0.062941509 | N10: 44317 | O10: 0.725 | P10: =(O10-O9)/O9 -> -0.02027027 | R10: 44317 | S10: 3.52 | T10: =(S10-S9)/S9 -> 0.038348083 | V10: 44317 | W10: 5.21 | X10: =(W10-W9)/W9 -> -0.054446461 | Z10: 44317 | AA10: 99.72 | AB10: =(AA10-AA9)/AA9 -> 0.11994609 | AD10: 44317 | AE10: 11.0327 | AF10: =(AE10-AE9)/AE9 -> 0.05803884 | AK10: (ASX:TLS) | AL10: Telstra Group Limited | AM10: Communication services | AN10: S3 | AO10: S31
A11: 5 | B11: 44348 | C11: 58.72 | D11: =(C11-C10)/C10 -> 0.27347647 | F11: 44348 | G11: 0.265 | H11: =(G11-G10)/G10 -> 0 | J11: 44348 | K11: 137.1 | L11: =(K11-K10)/K10 -> 0.033546928 | N11: 44348 | O11: 0.63 | P11: =(O11-O10)/O10 -> -0.13103448 | R11: 44348 | S11: 3.76 | T11: =(S11-S10)/S10 -> 0.068181818 | V11: 44348 | W11: 6.26 | X11: =(W11-W10)/W10 -> 0.20153551 | Z11: 44348 | AA11: 99.87 | AB11: =(AA11-AA10)/AA10 -> 0.0015042118 | AD11: 44348 | AE11: 11.0228 | AF11: =(AE11-AE10)/AE10 -> -0.00089733248 | AK11: (ASX:TPG) | AL11: TPG Telecom Limited | AO11: S32
A12: 6 | B12: 44378 | C12: 57.98 | D12: =(C12-C11)/C11 -> -0.01260218 | F12: 44378 | G12: 0.26 | H12: =(G12-G11)/G11 -> -0.018867925 | J12: 44378 | K12: 140.28 | L12: =(K12-K11)/K11 -> 0.023194748 | N12: 44378 | O12: 0.61 | P12: =(O12-O11)/O11 -> -0.031746032 | R12: 44378 | S12: 3.78 | T12: =(S12-S11)/S11 -> 0.0053191489 | V12: 44378 | W12: 6.18 | X12: =(W12-W11)/W11 -> -0.012779553 | Z12: 44378 | AA12: 99.65 | AB12: =(AA12-AA11)/AA11 -> -0.0022028637 | AD12: 44378 | AE12: 11.4494 | AF12: =(AE12-AE11)/AE11 -> 0.0387016 | AK12: (ASX:CBA) | AL12: Commonwealth Bank | AM12: Financial Services | AN12: S4 | AO12: S41
A13: 7 | B13: 44409 | C13: 63.07 | D13: =(C13-C12)/C12 -> 0.087788893 | F13: 44409 | G13: 0.3 | H13: =(G13-G12)/G12 -> 0.15384615 | J13: 44409 | K13: 151.82 | L13: =(K13-K12)/K12 -> 0.082264043 | N13: 44409 | O13: 0.69 | P13: =(O13-O12)/O12 -> 0.13114754 | R13: 44409 | S13: 3.84 | T13: =(S13-S12)/S12 -> 0.015873016 | V13: 44409 | W13: 6.16 | X13: =(W13-W12)/W12 -> -0.003236246 | Z13: 44409 | AA13: 100.12 | AB13: =(AA13-AA12)/AA12 -> 0.0047165078 | AD13: 44409 | AE13: 12.4601 | AF13: =(AE13-AE12)/AE12 -> 0.088275368 | AK13: (ASX:SUN) | AL13: Suncorp Group Limited | AO13: S42
A14: 8 | B14: 44440 | C14: 54.61 | D14: =(C14-C13)/C13 -> -0.13413667 | F14: 44440 | G14: 0.305 | H14: =(G14-G13)/G13 -> 0.016666667 | J14: 44440 | K14: 139 | L14: =(K14-K13)/K13 -> -0.084442102 | N14: 44440 | O14: 0.685 | P14: =(O14-O13)/O13 -> -0.0072463768 | R14: 44440 | S14: 3.93 | T14: =(S14-S13)/S13 -> 0.0234375 | V14: 44440 | W14: 7.06 | X14: =(W14-W13)/W13 -> 0.1461039 | Z14: 44440 | AA14: 104.33 | AB14: =(AA14-AA13)/AA13 -> 0.042049541 | AD14: 44440 | AE14: 12.5399 | AF14: =(AE14-AE13)/AE13 -> 0.006404443
A15: 9 | B15: 44470 | C15: 53.28 | D15: =(C15-C14)/C14 -> -0.024354514 | F15: 44470 | G15: 0.285 | H15: =(G15-G14)/G14 -> -0.06557377 | J15: 44470 | K15: 149.51 | L15: =(K15-K14)/K14 -> 0.075611511 | N15: 44470 | O15: 0.58 | P15: =(O15-O14)/O14 -> -0.15328467 | R15: 44470 | S15: 3.82 | T15: =(S15-S14)/S14 -> -0.027989822 | V15: 44470 | W15: 6.75 | X15: =(W15-W14)/W14 -> -0.043909348 | Z15: 44470 | AA15: 104.68 | AB15: =(AA15-AA14)/AA14 -> 0.0033547398 | AD15: 44470 | AE15: 11.7013 | AF15: =(AE15-AE14)/AE14 -> -0.066874536
A16: 10 | B16: 44501 | C16: 62.48 | D16: =(C16-C15)/C15 -> 0.17267267 | F16: 44501 | G16: 0.3 | H16: =(G16-G15)/G15 -> 0.052631579 | J16: 44501 | K16: 144.84 | L16: =(K16-K15)/K15 -> -0.031235369 | N16: 44501 | O16: 0.61 | P16: =(O16-O15)/O15 -> 0.051724138 | R16: 44501 | S16: 4.07 | T16: =(S16-S15)/S15 -> 0.065445026 | V16: 44501 | W16: 6.75 | X16: =(W16-W15)/W15 -> 0 | Z16: 44501 | AA16: 93.18 | AB16: =(AA16-AA15)/AA15 -> -0.10985862 | AD16: 44501 | AE16: 10.8027 | AF16: =(AE16-AE15)/AE15 -> -0.076794886
A17: 11 | B17: 44531 | C17: 62.44 | D17: =(C17-C16)/C16 -> -0.00064020487 | F17: 44531 | G17: 0.36 | H17: =(G17-G16)/G16 -> 0.2 | J17: 44531 | K17: 141.44 | L17: =(K17-K16)/K16 -> -0.023474178 | N17: 44531 | O17: 0.64 | P17: =(O17-O16)/O16 -> 0.049180328 | R17: 44531 | S17: 4.18 | T17: =(S17-S16)/S16 -> 0.027027027 | V17: 44531 | W17: 5.89 | X17: =(W17-W16)/W16 -> -0.12740741 | Z17: 44531 | AA17: 101 | AB17: =(AA17-AA16)/AA16 -> 0.083923589 | AD17: 44531 | AE17: 11.0523 | AF17: =(AE17-AE16)/AE16 -> 0.023105335
A18: 12 | B18: 44562 | C18: 45.1 | D18: =(C18-C17)/C17 -> -0.2777066 | F18: 44562 | G18: 0.35 | H18: =(G18-G17)/G17 -> -0.027777778 | J18: 44562 | K18: 112.91 | L18: =(K18-K17)/K17 -> -0.20171097 | N18: 44562 | O18: 0.645 | P18: =(O18-O17)/O17 -> 0.0078125 | R18: 44562 | S18: 3.92 | T18: =(S18-S17)/S17 -> -0.062200957 | V18: 44562 | W18: 5.9 | X18: =(W18-W17)/W17 -> 0.0016977929 | Z18: 44562 | AA18: 93.74 | AB18: =(AA18-AA17)/AA17 -> -0.071881188 | AD18: 44562 | AE18: 11.0224 | AF18: =(AE18-AE17)/AE17 -> -0.0027053193
A19: 13 | B19: 44593 | C19: 46.73 | D19: =(C19-C18)/C18 -> 0.036141907 | F19: 44593 | G19: 0.38 | H19: =(G19-G18)/G18 -> 0.085714286 | J19: 44593 | K19: 93.73 | L19: =(K19-K18)/K18 -> -0.16986981 | N19: 44593 | O19: 0.66 | P19: =(O19-O18)/O18 -> 0.023255814 | R19: 44593 | S19: 3.96 | T19: =(S19-S18)/S18 -> 0.010204082 | V19: 44593 | W19: 5.59 | X19: =(W19-W18)/W18 -> -0.052542373 | Z19: 44593 | AA19: 93.46 | AB19: =(AA19-AA18)/AA18 -> -0.0029869853 | AD19: 44593 | AE19: 10.7528 | AF19: =(AE19-AE18)/AE18 -> -0.024459283
A20: 14 | B20: 44621 | C20: 48.99 | D20: =(C20-C19)/C19 -> 0.048362936 | F20: 44621 | G20: 0.45 | H20: =(G20-G19)/G19 -> 0.18421053 | J20: 44621 | K20: 102.75 | L20: =(K20-K19)/K19 -> 0.096233863 | N20: 44621 | O20: 0.69 | P20: =(O20-O19)/O19 -> 0.045454545 | R20: 44621 | S20: 3.96 | T20: =(S20-S19)/S19 -> 0 | V20: 44621 | W20: 6.05 | X20: =(W20-W19)/W19 -> 0.082289803 | Z20: 44621 | AA20: 105.77 | AB20: =(AA20-AA19)/AA19 -> 0.1317141 | AD20: 44621 | AE20: 11.1022 | AF20: =(AE20-AE19)/AE19 -> 0.032493862
A21: 15 | B21: 44652 | C21: 47.48 | D21: =(C21-C20)/C20 -> -0.030822617 | F21: 44652 | G21: 0.415 | H21: =(G21-G20)/G20 -> -0.077777778 | J21: 44652 | K21: 96.35 | L21: =(K21-K20)/K20 -> -0.062287105 | N21: 44652 | O21: 0.68 | P21: =(O21-O20)/O20 -> -0.014492754 | R21: 44652 | S21: 4.04 | T21: =(S21-S20)/S20 -> 0.02020202 | V21: 44652 | W21: 5.88 | X21: =(W21-W20)/W20 -> -0.028099174 | Z21: 44652 | AA21: 103.88 | AB21: =(AA21-AA20)/AA20 -> -0.017868961 | AD21: 44652 | AE21: 11.4417 | AF21: =(AE21-AE20)/AE20 -> 0.030579525
A22: 16 | B22: 44682 | C22: 42.13 | D22: =(C22-C21)/C21 -> -0.11267902 | F22: 44682 | G22: 0.315 | H22: =(G22-G21)/G21 -> -0.24096386 | J22: 44682 | K22: 89.29 | L22: =(K22-K21)/K21 -> -0.07327452 | N22: 44682 | O22: 0.57 | P22: =(O22-O21)/O21 -> -0.16176471 | R22: 44682 | S22: 3.88 | T22: =(S22-S21)/S21 -> -0.03960396 | V22: 44682 | W22: 5.75 | X22: =(W22-W21)/W21 -> -0.022108844 | Z22: 44682 | AA22: 104.36 | AB22: =(AA22-AA21)/AA21 -> 0.0046207162 | AD22: 44682 | AE22: 11.3319 | AF22: =(AE22-AE21)/AE21 -> -0.009596476
A23: 17 | B23: 44713 | C23: 42.25 | D23: =(C23-C22)/C22 -> 0.0028483266 | F23: 44713 | G23: 0.28 | H23: =(G23-G22)/G22 -> -0.11111111 | J23: 44713 | K23: 76.96 | L23: =(K23-K22)/K22 -> -0.13808937 | N23: 44713 | O23: 0.555 | P23: =(O23-O22)/O22 -> -0.026315789 | R23: 44713 | S23: 3.85 | T23: =(S23-S22)/S22 -> -0.0077319588 | V23: 44713 | W23: 5.97 | X23: =(W23-W22)/W22 -> 0.03826087 | Z23: 44713 | AA23: 90.38 | AB23: =(AA23-AA22)/AA22 -> -0.13395937 | AD23: 44713 | AE23: 10.9625 | AF23: =(AE23-AE22)/AE22 -> -0.03259824
A24: 18 | B24: 44743 | C24: 49.54 | D24: =(C24-C23)/C23 -> 0.17254438 | F24: 44743 | G24: 0.315 | H24: =(G24-G23)/G23 -> 0.125 | J24: 44743 | K24: 92.99 | L24: =(K24-K23)/K23 -> 0.20829002 | N24: 44743 | O24: 0.6 | P24: =(O24-O23)/O23 -> 0.081081081 | R24: 44743 | S24: 3.89 | T24: =(S24-S23)/S23 -> 0.01038961 | V24: 44743 | W24: 6.34 | X24: =(W24-W23)/W23 -> 0.061976549 | Z24: 44743 | AA24: 100.77 | AB24: =(AA24-AA23)/AA23 -> 0.11495906 | AD24: 44743 | AE24: 11.1721 | AF24: =(AE24-AE23)/AE23 -> 0.019119726
A25: 19 | B25: 44774 | C25: 54.48 | D25: =(C25-C24)/C24 -> 0.0997174 | F25: 44774 | G25: 0.39 | H25: =(G25-G24)/G24 -> 0.23809524 | J25: 44774 | K25: 87.75 | L25: =(K25-K24)/K24 -> -0.056350145 | N25: 44774 | O25: 0.615 | P25: =(O25-O24)/O24 -> 0.025 | R25: 44774 | S25: 3.97 | T25: =(S25-S24)/S24 -> 0.020565553 | V25: 44774 | W25: 5.35 | X25: =(W25-W24)/W24 -> -0.15615142 | Z25: 44774 | AA25: 97.47 | AB25: =(AA25-AA24)/AA24 -> -0.032747842 | AD25: 44774 | AE25: 10.8826 | AF25: =(AE25-AE24)/AE24 -> -0.025912765
... A54: 48 | B54: 45658 | C54: 278.4 | D54: =(C54-C53)/C53 -> 0.11306573 | F54: 45658 | G54: 0.545 | H54: =(G54-G53)/G53 -> 0.13541667 | J54: 45658 | K54: 183.27 | L54: =(K54-K53)/K53 -> 0.087268628 | N54: 45658 | O54: 0.94 | P54: =(O54-O53)/O53 -> -0.096153846 | R54: 45658 | S54: 3.95 | T54: =(S54-S53)/S53 -> -0.014962594 | V54: 45658 | W54: 4.4 | X54: =(W54-W53)/W53 -> -0.020044543 | Z54: 45658 | AA54: 160.56 | AB54: =(AA54-AA53)/AA53 -> 0.047699837 | AD54: 45658 | AE54: 20.7767 | AF54: =(AE54-AE53)/AE53 -> 0.094685873
D55: =AVERAGE(D7:D54) -> 0.045530186 | H55: =AVERAGE(H7:H54) -> 0.025564443 | L55: =AVERAGE(L7:L54) -> 0.011564818 | P55: =AVERAGE(P7:P54) -> 0.010884127 | T55: =AVERAGE(T7:T54) -> 0.0055431375 | X55: =AVERAGE(X7:X54) -> -0.0082112647 | AB55: =AVERAGE(AB7:AB54) -> 0.015632543 | AF55: =AVERAGE(AF7:AF54) -> 0.016484699

Sheet 1.b Sample  (Return and Risk)
C2: Table 1.b.1 | Q2: Complete all three tables
B3: monthly rate of return | C3: S11 | D3: S12 | E3: S21 | F3: S22 | G3: S31 | H3: S32 | I3: S41 | J3: S42
C4: 1 | D4: 2 | E4: 3 | F4: 4 | G4: 5 | H4: 6 | I4: 7 | J4: 8 | Q4: Table 1.b.2
B5: Date | C5: Monthly rate of return of Pro Medicus Limited | D5: Monthly rate of return of Paragon Care Limited | E5: Monthly rate of return of Xero Limited | F5: Monthly rate of COSOL Limited | G5: Monthly rate of return of Telstra Group Limited | H5: Monthly rate of return of TPG Telecom Limited | I5: Monthly rate of return of Commonwealth Bank | J5: Monthly rate of return of Suncorp Group Limited | P5: Symbol | Q5: Company | R5: Category | S5: Category code | T5: Category sub code for chosen assests | U5: Average 4 year return | V5: Stnd Deviation of 4 years | W5: Risk Category (R1 / R2 /R3)
B6: Code | C6: (ASX.PME) | D6: (ASX:PGC) | E6: (ASX:XRO) | F6: (ASX:COS) | G6: (ASX:TLS) | H6: (ASX:TPG) | I6: (ASX:CBA) | J6: (ASX:SUN) | P6: (ASX:PME) | Q6: Pro Medicus Limited | R6: Healthcare | S6: S1 | T6: S11 | U6: =C56 -> 0.045530186 | V6: =C57 -> 0.10936386 | W6: R3 (High Risk)
A7: 0 | B7: 44197 | P7: (ASX:PGC) | Q7: Paragon Care Limited | T7: S12 | U7: =D56 -> 0.025564443 | V7: =D57 -> 0.13553167 | W7: R3 (High Risk)
A8: 1 | B8: 44228 | C8: ='1.a Compute rate of return'!D7 -> 0.035247432 | D8: ='1.a Compute rate of return'!H7 -> 0.125 | E8: ='1.a Compute rate of return'!L7 -> -0.088228501 | F8: ='1.a Compute rate of return'!P7 -> 0 | G8: ='1.a Compute rate of return'!T7 -> -0.012820513 | H8: ='1.a Compute rate of return'!X7 -> -0.081081081 | I8: ='1.a Compute rate of return'!AB7 -> -0.023350497 | J8: ='1.a Compute rate of return'!AF7 -> -0.01388875 | P8: (ASX:XRO) | Q8: Xero Limited | R8: Technology | S8: S2 | T8: S21 | U8: =E56 -> 0.011564818 | V8: =E57 -> 0.094151229 | W8: R2 (Medium Risk)
A9: 2 | B9: 44256 | C9: ='1.a Compute rate of return'!D8 -> -0.068094701 | D9: ='1.a Compute rate of return'!H8 -> -0.11111111 | E9: ='1.a Compute rate of return'!L8 -> 0.068394832 | F9: ='1.a Compute rate of return'!P8 -> 0.15384615 | G9: ='1.a Compute rate of return'!T8 -> 0.1038961 | H9: ='1.a Compute rate of return'!X8 -> -0.069117647 | I9: ='1.a Compute rate of return'!AB8 -> 0.055664541 | J9: ='1.a Compute rate of return'!AF8 -> -0.0040255526 | P9: (ASX:COS) | Q9: COSOL Limited | T9: S22 | U9: =F56 -> 0.010884127 | V9: =F57 -> 0.080188898 | W9: R2 (Medium Risk)
A10: 3 | B10: 44287 | C10: ='1.a Compute rate of return'!D9 -> 0.14226954 | D10: ='1.a Compute rate of return'!H9 -> -0.0625 | E10: ='1.a Compute rate of return'!L9 -> 0.11878606 | F10: ='1.a Compute rate of return'!P9 -> -0.013333333 | G10: ='1.a Compute rate of return'!T9 -> -0.0029411765 | H10: ='1.a Compute rate of return'!X9 -> -0.12954186 | I10: ='1.a Compute rate of return'!AB9 -> 0.034146341 | J10: ='1.a Compute rate of return'!AF9 -> 0.061614897 | P10: (ASX:TLS) | Q10: Telstra Group Limited | R10: Communication services | S10: S3 | T10: S31 | U10: =G56 -> 0.0055431375 | V10: =G57 -> 0.035698466 | W10: R1 (Low risk)
A11: 4 | B11: 44317 | C11: ='1.a Compute rate of return'!D10 -> -0.023300148 | D11: ='1.a Compute rate of return'!H10 -> 0.17777778 | E11: ='1.a Compute rate of return'!L10 -> -0.062941509 | F11: ='1.a Compute rate of return'!P10 -> -0.02027027 | G11: ='1.a Compute rate of return'!T10 -> 0.038348083 | H11: ='1.a Compute rate of return'!X10 -> -0.054446461 | I11: ='1.a Compute rate of return'!AB10 -> 0.11994609 | J11: ='1.a Compute rate of return'!AF10 -> 0.05803884 | P11: (ASX:TPG) | Q11: TPG Telecom Limited | T11: S32 | U11: =H56 -> -0.0082112647 | V11: =H57 -> 0.07254004 | W11: R2 (Medium Risk)
A12: 5 | B12: 44348 | C12: ='1.a Compute rate of return'!D11 -> 0.27347647 | D12: ='1.a Compute rate of return'!H11 -> 0 | E12: ='1.a Compute rate of return'!L11 -> 0.033546928 | F12: ='1.a Compute rate of return'!P11 -> -0.13103448 | G12: ='1.a Compute rate of return'!T11 -> 0.068181818 | H12: ='1.a Compute rate of return'!X11 -> 0.20153551 | I12: ='1.a Compute rate of return'!AB11 -> 0.0015042118 | J12: ='1.a Compute rate of return'!AF11 -> -0.00089733248 | P12: (ASX:CBA) | Q12: Commonwealth Bank | R12: Financial Services | S12: S4 | T12: S41 | U12: =I56 -> 0.015632543 | V12: =I57 -> 0.062967476 | W12: R1 (Low risk)
A13: 6 | B13: 44378 | C13: ='1.a Compute rate of return'!D12 -> -0.01260218 | D13: ='1.a Compute rate of return'!H12 -> -0.018867925 | E13: ='1.a Compute rate of return'!L12 -> 0.023194748 | F13: ='1.a Compute rate of return'!P12 -> -0.031746032 | G13: ='1.a Compute rate of return'!T12 -> 0.0053191489 | H13: ='1.a Compute rate of return'!X12 -> -0.012779553 | I13: ='1.a Compute rate of return'!AB12 -> -0.0022028637 | J13: ='1.a Compute rate of return'!AF12 -> 0.0387016 | P13: (ASX:SUN) | Q13: Suncorp Group Limited | T13: S42 | U13: =J56 -> 0.016484699 | V13: =J57 -> 0.048592931 | W13: R1 (Low risk)
A14: 7 | B14: 44409 | C14: ='1.a Compute rate of return'!D13 -> 0.087788893 | D14: ='1.a Compute rate of return'!H13 -> 0.15384615 | E14: ='1.a Compute rate of return'!L13 -> 0.082264043 | F14: ='1.a Compute rate of return'!P13 -> 0.13114754 | G14: ='1.a Compute rate of return'!T13 -> 0.015873016 | H14: ='1.a Compute rate of return'!X13 -> -0.003236246 | I14: ='1.a Compute rate of return'!AB13 -> 0.0047165078 | J14: ='1.a Compute rate of return'!AF13 -> 0.088275368
A15: 8 | B15: 44440 | C15: ='1.a Compute rate of return'!D14 -> -0.13413667 | D15: ='1.a Compute rate of return'!H14 -> 0.016666667 | E15: ='1.a Compute rate of return'!L14 -> -0.084442102 | F15: ='1.a Compute rate of return'!P14 -> -0.0072463768 | G15: ='1.a Compute rate of return'!T14 -> 0.0234375 | H15: ='1.a Compute rate of return'!X14 -> 0.1461039 | I15: ='1.a Compute rate of return'!AB14 -> 0.042049541 | J15: ='1.a Compute rate of return'!AF14 -> 0.006404443
A16: 9 | B16: 44470 | C16: ='1.a Compute rate of return'!D15 -> -0.024354514 | D16: ='1.a Compute rate of return'!H15 -> -0.06557377 | E16: ='1.a Compute rate of return'!L15 -> 0.075611511 | F16: ='1.a Compute rate of return'!P15 -> -0.15328467 | G16: ='1.a Compute rate of return'!T15 -> -0.027989822 | H16: ='1.a Compute rate of return'!X15 -> -0.043909348 | I16: ='1.a Compute rate of return'!AB15 -> 0.0033547398 | J16: ='1.a Compute rate of return'!AF15 -> -0.066874536 | Q16: Table 1.b.3
A17: 10 | B17: 44501 | C17: ='1.a Compute rate of return'!D16 -> 0.17267267 | D17: ='1.a Compute rate of return'!H16 -> 0.052631579 | E17: ='1.a Compute rate of return'!L16 -> -0.031235369 | F17: ='1.a Compute rate of return'!P16 -> 0.051724138 | G17: ='1.a Compute rate of return'!T16 -> 0.065445026 | H17: ='1.a Compute rate of return'!X16 -> 0 | I17: ='1.a Compute rate of return'!AB16 -> -0.10985862 | J17: ='1.a Compute rate of return'!AF16 -> -0.076794886 | Q17: Health Care S1 | S17: Technology S2 | U17: Communi. Services S3 | W17: Financial. Ser S4
A18: 11 | B18: 44531 | C18: ='1.a Compute rate of return'!D17 -> -0.00064020487 | D18: ='1.a Compute rate of return'!H17 -> 0.2 | E18: ='1.a Compute rate of return'!L17 -> -0.023474178 | F18: ='1.a Compute rate of return'!P17 -> 0.049180328 | G18: ='1.a Compute rate of return'!T17 -> 0.027027027 | H18: ='1.a Compute rate of return'!X17 -> -0.12740741 | I18: ='1.a Compute rate of return'!AB17 -> 0.083923589 | J18: ='1.a Compute rate of return'!AF17 -> 0.023105335 | Q18: S11 | R18: S12 | S18: S21 | T18: S22 | U18: S31 | V18: S32 | W18: S41 | X18: S42 | Y18: Total
A19: 12 | B19: 44562 | C19: ='1.a Compute rate of return'!D18 -> -0.2777066 | D19: ='1.a Compute rate of return'!H18 -> -0.027777778 | E19: ='1.a Compute rate of return'!L18 -> -0.20171097 | F19: ='1.a Compute rate of return'!P18 -> 0.0078125 | G19: ='1.a Compute rate of return'!T18 -> -0.062200957 | H19: ='1.a Compute rate of return'!X18 -> 0.0016977929 | I19: ='1.a Compute rate of return'!AB18 -> -0.071881188 | J19: ='1.a Compute rate of return'!AF18 -> -0.0027053193 | P19: R1 | U19: (ASX:TLS) | W19: (ASX:CBA) | X19: (ASX:SUN) | Y19: at least two investments
A20: 13 | B20: 44593 | C20: ='1.a Compute rate of return'!D19 -> 0.036141907 | D20: ='1.a Compute rate of return'!H19 -> 0.085714286 | E20: ='1.a Compute rate of return'!L19 -> -0.16986981 | F20: ='1.a Compute rate of return'!P19 -> 0.023255814 | G20: ='1.a Compute rate of return'!T19 -> 0.010204082 | H20: ='1.a Compute rate of return'!X19 -> -0.052542373 | I20: ='1.a Compute rate of return'!AB19 -> -0.0029869853 | J20: ='1.a Compute rate of return'!AF19 -> -0.024459283 | P20: R2 | S20: (ASX:XRO) | T20: (ASX:COS) | V20: (ASX:TPG) | Y20: at least two investments
A21: 14 | B21: 44621 | C21: ='1.a Compute rate of return'!D20 -> 0.048362936 | D21: ='1.a Compute rate of return'!H20 -> 0.18421053 | E21: ='1.a Compute rate of return'!L20 -> 0.096233863 | F21: ='1.a Compute rate of return'!P20 -> 0.045454545 | G21: ='1.a Compute rate of return'!T20 -> 0 | H21: ='1.a Compute rate of return'!X20 -> 0.082289803 | I21: ='1.a Compute rate of return'!AB20 -> 0.1317141 | J21: ='1.a Compute rate of return'!AF20 -> 0.032493862 | P21: R3 | Q21: (ASX:PME) | R21: (ASX:PGC) | Y21: at least two investments
A22: 15 | B22: 44652 | C22: ='1.a Compute rate of return'!D21 -> -0.030822617 | D22: ='1.a Compute rate of return'!H21 -> -0.077777778 | E22: ='1.a Compute rate of return'!L21 -> -0.062287105 | F22: ='1.a Compute rate of return'!P21 -> -0.014492754 | G22: ='1.a Compute rate of return'!T21 -> 0.02020202 | H22: ='1.a Compute rate of return'!X21 -> -0.028099174 | I22: ='1.a Compute rate of return'!AB21 -> -0.017868961 | J22: ='1.a Compute rate of return'!AF21 -> 0.030579525
A23: 16 | B23: 44682 | C23: ='1.a Compute rate of return'!D22 -> -0.11267902 | D23: ='1.a Compute rate of return'!H22 -> -0.24096386 | E23: ='1.a Compute rate of return'!L22 -> -0.07327452 | F23: ='1.a Compute rate of return'!P22 -> -0.16176471 | G23: ='1.a Compute rate of return'!T22 -> -0.03960396 | H23: ='1.a Compute rate of return'!X22 -> -0.022108844 | I23: ='1.a Compute rate of return'!AB22 -> 0.0046207162 | J23: ='1.a Compute rate of return'!AF22 -> -0.009596476
A24: 17 | B24: 44713 | C24: ='1.a Compute rate of return'!D23 -> 0.0028483266 | D24: ='1.a Compute rate of return'!H23 -> -0.11111111 | E24: ='1.a Compute rate of return'!L23 -> -0.13808937 | F24: ='1.a Compute rate of return'!P23 -> -0.026315789 | G24: ='1.a Compute rate of return'!T23 -> -0.0077319588 | H24: ='1.a Compute rate of return'!X23 -> 0.03826087 | I24: ='1.a Compute rate of return'!AB23 -> -0.13395937 | J24: ='1.a Compute rate of return'!AF23 -> -0.03259824
A25: 18 | B25: 44743 | C25: ='1.a Compute rate of return'!D24 -> 0.17254438 | D25: ='1.a Compute rate of return'!H24 -> 0.125 | E25: ='1.a Compute rate of return'!L24 -> 0.20829002 | F25: ='1.a Compute rate of return'!P24 -> 0.081081081 | G25: ='1.a Compute rate of return'!T24 -> 0.01038961 | H25: ='1.a Compute rate of return'!X24 -> 0.061976549 | I25: ='1.a Compute rate of return'!AB24 -> 0.11495906 | J25: ='1.a Compute rate of return'!AF24 -> 0.019119726
A26: 19 | B26: 44774 | C26: ='1.a Compute rate of return'!D25 -> 0.0997174 | D26: ='1.a Compute rate of return'!H25 -> 0.23809524 | E26: ='1.a Compute rate of return'!L25 -> -0.056350145 | F26: ='1.a Compute rate of return'!P25 -> 0.025 | G26: ='1.a Compute rate of return'!T25 -> 0.020565553 | H26: ='1.a Compute rate of return'!X25 -> -0.15615142 | I26: ='1.a Compute rate of return'!AB25 -> -0.032747842 | J26: ='1.a Compute rate of return'!AF25 -> -0.025912765
A27: 20 | B27: 44805 | C27: ='1.a Compute rate of return'!D26 -> -0.078744493 | D27: ='1.a Compute rate of return'!H26 -> -0.15384615 | E27: ='1.a Compute rate of return'!L26 -> -0.1622792 | F27: ='1.a Compute rate of return'!P26 -> -0.0081300813 | G27: ='1.a Compute rate of return'!T26 -> -0.0302267 | H27: ='1.a Compute rate of return'!X26 -> -0.093457944 | I27: ='1.a Compute rate of return'!AB26 -> -0.069457269 | J27: ='1.a Compute rate of return'!AF26 -> -0.079815485
A28: 21 | B28: 44835 | C28: ='1.a Compute rate of return'!D27 -> 0.11217374 | D28: ='1.a Compute rate of return'!H27 -> 0.045454545 | E28: ='1.a Compute rate of return'!L27 -> 0.062032377 | F28: ='1.a Compute rate of return'!P27 -> 0 | G28: ='1.a Compute rate of return'!T27 -> 0.018181818 | H28: ='1.a Compute rate of return'!X27 -> 0.010309278 | I28: ='1.a Compute rate of return'!AB27 -> 0.15413451 | J28: ='1.a Compute rate of return'!AF27 -> 0.13758738
A29: 22 | B29: 44866 | C29: ='1.a Compute rate of return'!D28 -> 0.064851308 | D29: ='1.a Compute rate of return'!H28 -> 0.014492754 | E29: ='1.a Compute rate of return'!L28 -> -0.095171 | F29: ='1.a Compute rate of return'!P28 -> 0.12295082 | G29: ='1.a Compute rate of return'!T28 -> 0.015306122 | H29: ='1.a Compute rate of return'!X28 -> -0.0020408163 | I29: ='1.a Compute rate of return'!AB28 -> 0.030378296 | J29: ='1.a Compute rate of return'!AF28 -> 0.044698818
A30: 23 | B30: 44896 | C30: ='1.a Compute rate of return'!D29 -> -0.070323015 | D30: ='1.a Compute rate of return'!H29 -> -0.1 | E30: ='1.a Compute rate of return'!L29 -> -0.0052378256 | F30: ='1.a Compute rate of return'!P29 -> 0.094890511 | G30: ='1.a Compute rate of return'!T29 -> 0.0025125628 | H30: ='1.a Compute rate of return'!X29 -> 0 | I30: ='1.a Compute rate of return'!AB29 -> -0.04876692 | J30: ='1.a Compute rate of return'!AF29 -> 0.010066381 | U30: Stock
A31: 24 | B31: 44927 | C31: ='1.a Compute rate of return'!D30 -> 0.20973579 | D31: ='1.a Compute rate of return'!H30 -> -0.063492063 | E31: ='1.a Compute rate of return'!L30 -> 0.09292728 | F31: ='1.a Compute rate of return'!P30 -> 0.11 | G31: ='1.a Compute rate of return'!T30 -> 0.022556391 | H31: ='1.a Compute rate of return'!X30 -> -0.014314928 | I31: ='1.a Compute rate of return'!AB30 -> 0.072709552 | J31: ='1.a Compute rate of return'!AF30 -> 0.040696127 | T31: (ASX:PME) | U31: 0.10936386
A32: 25 | B32: 44958 | C32: ='1.a Compute rate of return'!D31 -> -0.087359761 | D32: ='1.a Compute rate of return'!H31 -> -0.10169492 | E32: ='1.a Compute rate of return'!L31 -> 0.01171875 | F32: ='1.a Compute rate of return'!P31 -> -0.039039039 | G32: ='1.a Compute rate of return'!T31 -> 0.019607843 | H32: ='1.a Compute rate of return'!X31 -> 0.05186722 | I32: ='1.a Compute rate of return'!AB31 -> -0.085135381 | J32: ='1.a Compute rate of return'!AF31 -> 0.025539568 | T32: (ASX:PGC) | U32: 0.13553167
A33: 26 | B33: 44986 | C33: ='1.a Compute rate of return'!D32 -> 0.046877561 | D33: ='1.a Compute rate of return'!H32 -> -0.075471698 | E33: ='1.a Compute rate of return'!L32 -> 0.15083655 | F33: ='1.a Compute rate of return'!P32 -> 0.05 | G33: ='1.a Compute rate of return'!T32 -> 0.014423077 | H33: ='1.a Compute rate of return'!X32 -> -0.037475345 | I33: ='1.a Compute rate of return'!AB32 -> -0.023537591 | J33: ='1.a Compute rate of return'!AF32 -> -0.057593827 | T33: (ASX:XRO) | U33: 0.094151229
A34: 27 | B34: 45017 | C34: ='1.a Compute rate of return'!D33 -> -0.038046031 | D34: ='1.a Compute rate of return'!H33 -> 0.14285714 | E34: ='1.a Compute rate of return'!L33 -> 0.043838068 | F34: ='1.a Compute rate of return'!P33 -> -0.023809524 | G34: ='1.a Compute rate of return'!T33 -> 0.035545024 | H34: ='1.a Compute rate of return'!X33 -> 0.10040984 | I34: ='1.a Compute rate of return'!AB33 -> 0.010577705 | J34: ='1.a Compute rate of return'!AF33 -> 0.030560932 | T34: (ASX:COS) | U34: 0.080188898
A35: 28 | B35: 45047 | C35: ='1.a Compute rate of return'!D34 -> -0.034016927 | D35: ='1.a Compute rate of return'!H34 -> -0.10714286 | E35: ='1.a Compute rate of return'!L34 -> 0.17795157 | F35: ='1.a Compute rate of return'!P34 -> -0.042682927 | G35: ='1.a Compute rate of return'!T34 -> -0.0022883295 | H35: ='1.a Compute rate of return'!X34 -> 0.018621974 | I35: ='1.a Compute rate of return'!AB34 -> -0.025966184 | J35: ='1.a Compute rate of return'!AF34 -> 0.065697707 | T35: (ASX:TLS) | U35: 0.035698466
A36: 29 | B36: 45078 | C36: ='1.a Compute rate of return'!D35 -> 0.10598147 | D36: ='1.a Compute rate of return'!H35 -> -0.06 | E36: ='1.a Compute rate of return'!L35 -> 0.081673488 | F36: ='1.a Compute rate of return'!P35 -> -0.025477707 | G36: ='1.a Compute rate of return'!T35 -> -0.013761468 | H36: ='1.a Compute rate of return'!X35 -> -0.10968921 | I36: ='1.a Compute rate of return'!AB35 -> 0.03606117 | J36: ='1.a Compute rate of return'!AF35 -> 0.014286037 | T36: (ASX:TPG) | U36: 0.07254004
A37: 30 | B37: 45108 | C37: ='1.a Compute rate of return'!D36 -> 0.047989031 | D37: ='1.a Compute rate of return'!H36 -> -0.021276596 | E37: ='1.a Compute rate of return'!L36 -> 0.027579248 | F37: ='1.a Compute rate of return'!P36 -> 0.071895425 | G37: ='1.a Compute rate of return'!T36 -> -0.0093023256 | H37: ='1.a Compute rate of return'!X36 -> 0.030800821 | I37: ='1.a Compute rate of return'!AB36 -> 0.054253516 | J37: ='1.a Compute rate of return'!AF36 -> 0.05486175 | T37: (ASX:CBA) | U37: 0.062967476
A38: 31 | B38: 45139 | C38: ='1.a Compute rate of return'!D37 -> 0.065852595 | D38: ='1.a Compute rate of return'!H37 -> -0.17391304 | E38: ='1.a Compute rate of return'!L37 -> 0.023647819 | F38: ='1.a Compute rate of return'!P37 -> 0.030487805 | G38: ='1.a Compute rate of return'!T37 -> -0.058685446 | H38: ='1.a Compute rate of return'!X37 -> 0.12151394 | I38: ='1.a Compute rate of return'!AB37 -> -0.033393246 | J38: ='1.a Compute rate of return'!AF37 -> -0.042168463 | T38: (ASX:SUN) | U38: 0.048592931
A39: 32 | B39: 45170 | C39: ='1.a Compute rate of return'!D38 -> 0.13734315 | D39: ='1.a Compute rate of return'!H38 -> -0.10526316 | E39: ='1.a Compute rate of return'!L38 -> -0.10127898 | F39: ='1.a Compute rate of return'!P38 -> 0.047337278 | G39: ='1.a Compute rate of return'!T38 -> -0.039900249 | H39: ='1.a Compute rate of return'!X38 -> -0.030195382 | I39: ='1.a Compute rate of return'!AB38 -> -0.021628499 | J39: ='1.a Compute rate of return'!AF38 -> 0.024948193
A40: 33 | B40: 45200 | C40: ='1.a Compute rate of return'!D39 -> -0.10612783 | D40: ='1.a Compute rate of return'!H39 -> 0.058823529 | E40: ='1.a Compute rate of return'!L39 -> -0.051053989 | F40: ='1.a Compute rate of return'!P39 -> -0.04519774 | G40: ='1.a Compute rate of return'!T39 -> -0.01038961 | H40: ='1.a Compute rate of return'!X39 -> -0.051282051 | I40: ='1.a Compute rate of return'!AB39 -> -0.034110233 | J40: ='1.a Compute rate of return'!AF39 -> -0.042236354
A41: 34 | B41: 45231 | C41: ='1.a Compute rate of return'!D40 -> 0.18607459 | D41: ='1.a Compute rate of return'!H40 -> 0.055555556 | E41: ='1.a Compute rate of return'!L40 -> -0.034117537 | F41: ='1.a Compute rate of return'!P40 -> -0.0059171598 | G41: ='1.a Compute rate of return'!T40 -> 0.0026246719 | H41: ='1.a Compute rate of return'!X40 -> -0.088803089 | I41: ='1.a Compute rate of return'!AB40 -> 0.083885667 | J41: ='1.a Compute rate of return'!AF40 -> 0.044098933
...

Sheet 2.a. LP Modelling
A1: LINEAR PROGRAMING
A3: INPUTS | C3: Healthcare | E3: Technology | G3: Communication Service | I3: Finance
C4: (ASX.PME) | D4: (ASX:PGC) | E4: (ASX:XRO) | F4: (ASX:COS) | G4: (ASX:TLS) | H4: (ASX:TPG) | I4: (ASX:CBA) | J4: (ASX:SUN)
B5: Stock | C5: S11 | D5: S12 | E5: S21 | F5: S22 | G5: S31 | H5: S32 | I5: S41 | J5: S42
B6: Mean | C6: 0.045530186 | D6: 0.025564443 | E6: 0.011564818 | F6: 0.010884127 | G6: 0.0055431375 | H6: -0.0082112647 | I6: 0.015632543 | J6: 0.016484699
A8: DECISION VARIABLES
B9: Risk category | C9: R3 (High Risk) | D9: R3 (High Risk) | E9: R2 (Medium Risk) | F9: R2 (Medium Risk) | G9: R1 (Low risk) | H9: R2 (Medium Risk) | I9: R1 (Low risk) | J9: R1 (Low risk)
B10: Stock | C10: (ASX.PME) | D10: (ASX:PGC) | E10: (ASX:XRO) | F10: (ASX:COS) | G10: (ASX:TLS) | H10: (ASX:TPG) | I10: (ASX:CBA) | J10: (ASX:SUN)
B11: Investment weights | C11: 0.1 | D11: 0.05 | E11: 0.1 | F11: 0.05 | G11: 0.1 | H11: 0.05 | I11: 0.05 | J11: 0.5
A14: OBJECTIVE FUNCTION
B16: Maxmize portfolio return | C16: =SUMPRODUCT(C6:J6,C11:J11) -> 0.016699656
A18: Constrains
C19: LHS | E19: RHS
A20: (High Risk assets should be less Than 15%) | C20: =SUM(C11+D11) -> 0.15 | D20: <= | E20: 0.15
A22: (Low risk stocks should be greater than Medium Risk stock(R2) | C22: =SUM(G11,I11,J11) -> 0.65 | D22: >= | E22: =SUM(E11,F11,H11) -> 0.2
A24: (Low Risk Stock Receive higest allocaton than R3. ) | C24: =SUM(G11,I11,J11) -> 0.65 | D24: >= | E24: =SUM(C11,D11) -> 0.15
A26: (Health care sector must have a minimum of 15% invested) | C26: =SUM(C11,D11) -> 0.15 | D26: >= | E26: 0.15
A28: (Technology sector must have a minimum of 15% invested) | C28: =SUM(E11,F11) -> 0.15 | D28: >= | E28: 0.15
A30: (Communication Service sector must have a minimum of 15% invested) | C30: =SUM(G11,H11) -> 0.15 | D30: >= | E30: 0.15
A32: (Finance sector must have a minimum of 20% invested) | C32: =SUM(I11,J11) -> 0.55 | D32: >= | E32: 0.2
A34: (minimum investment in each S11 should be 5%) | C34: =C11 -> 0.1 | D34: >= | E34: 0.05
A36: (minimum investment in each S12 should be 5%) | C36: =D11 -> 0.05 | D36: >= | E36: 0.05
A38: (minimum investment in each S21 should be 5%) | C38: =E11 -> 0.1 | D38: >= | E38: 0.05
A40: (minimum investment in each S22 should be 5%) | C40: =F11 -> 0.05 | D40: >= | E40: 0.05
A42: (minimum investment in each S31 should be 5%) | C42: =G11 -> 0.1 | D42: >= | E42: 0.05
A44: (minimum investment in each S32 should be 5%) | C44: =H11 -> 0.05 | D44: >= | E44: 0.05
A46: (minimum investment in each S41 should be 5%) | C46: =I11 -> 0.05 | D46: >= | E46: 0.05
A48: (minimum investment in each S42 should be 5%) | C48: =J11 -> 0.5 | D48: >= | E48: 0.05
A50: (Sum of all should be 100%) | C50: =SUM(C11:J11) -> 1 | D50: = | E50: 1
A52: non negative constrain | C52: =SUM(C11:J11) -> 1 | D52: >= | E52: 0

Sheet 2.b LP Sensitivity Report 
A1: Microsoft Excel 16.95 Sensitivity Report
A2: Worksheet: [BASKAR_GOKUL_S223638072_MIS775.xlsx]2.a. LP Modelling
A3: Report Created: 10/04/25 12:13:32 PM
A6: Variable Cells
D7: Final | E7: Reduced | F7: Objective | G7: Allowable | H7: Allowable
B8: Cell | C8: Name | D8: Value | E8: Cost | F8: Coefficient | G8: Increase | H8: Decrease
B9: $C$11 | C9: Investment weights (ASX.PME) | D9: 0.1 | E9: 0 | F9: 0.045530186 | G9: 1e+30 | H9: 0.019965743
B10: $D$11 | C10: Investment weights (ASX:PGC) | D10: 0.05 | E10: 0 | F10: 0.025564443 | G10: 0.019965743 | H10: 1e+30
B11: $E$11 | C11: Investment weights (ASX:XRO) | D11: 0.1 | E11: 0 | F11: 0.011564818 | G11: 0.0049198808 | H11: 0.00068069083
B12: $F$11 | C12: Investment weights (ASX:COS) | D12: 0.05 | E12: 0 | F12: 0.010884127 | G12: 0.00068069083 | H12: 1e+30
B13: $G$11 | C13: Investment weights (ASX:TLS) | D13: 0.1 | E13: 0 | F13: 0.0055431375 | G13: 0.010941561 | H13: 0.013754402
B14: $H$11 | C14: Investment weights (ASX:TPG) | D14: 0.05 | E14: 0 | F14: -0.0082112647 | G14: 0.013754402 | H14: 1e+30
B15: $I$11 | C15: Investment weights (ASX:CBA) | D15: 0.05 | E15: 0 | F15: 0.015632543 | G15: 0.00085215554 | H15: 1e+30
B16: $J$11 | C16: Investment weights (ASX:SUN) | D16: 0.5 | E16: 0 | F16: 0.016484699 | G16: 0.029045487 | H16: 0.00085215554
A18: Constraints
D19: Final | E19: Shadow | F19: Constraint | G19: Allowable | H19: Allowable
B20: Cell | C20: Name | D20: Value | E20: Price | F20: R.H. Side | G20: Increase | H20: Decrease
B21: $C$20 | C21: (High Risk assets should be less Than 15%) LHS | D21: 0.15 | E21: 0.029045487 | F21: 0.15 | G21: 0.25 | H21: 2.7755576e-18
B22: $C$22 | C22: (Low risk stocks should be greater than Medium Risk stock(R2) LHS | D22: 0.65 | E22: 0 | F22: 0 | G22: 0.45 | H22: 1e+30
B23: $C$24 | C23: (Low Risk Stock Receive higest allocaton than R3. ) LHS | D23: 0.65 | E23: 0 | F23: 0 | G23: 0.5 | H23: 1e+30
B24: $C$26 | C24: (Health care sector must have a minimum of 15% invested) LHS | D24: 0.15 | E24: 0 | F24: 0.15 | G24: 2.7755576e-18 | H24: 1e+30
B25: $C$28 | C25: (Technology sector must have a minimum of 15% invested) LHS | D25: 0.15 | E25: -0.0049198808 | F25: 0.15 | G25: 0.225 | H25: 0.05
B26: $C$30 | C26: (Communication Service sector must have a minimum of 15% invested) LHS | D26: 0.15 | E26: -0.010941561 | F26: 0.15 | G26: 0.35 | H26: 0.05
B27: $C$32 | C27: (Finance sector must have a minimum of 20% invested) LHS | D27: 0.55 | E27: 0 | F27: 0.2 | G27: 0.35 | H27: 1e+30
B28: $C$34 | C28: (minimum investment in each S11 should be 5%) LHS | D28: 0.1 | E28: 0 | F28: 0.05 | G28: 0.05 | H28: 1e+30
B29: $C$36 | C29: (minimum investment in each S12 should be 5%) LHS | D29: 0.05 | E29: -0.019965743 | F29: 0.05 | G29: 0.05 | H29: 1e+30
B30: $C$38 | C30: (minimum investment in each S21 should be 5%) LHS | D30: 0.1 | E30: 0 | F30: 0.05 | G30: 0.05 | H30: 1e+30
B31: $C$40 | C31: (minimum investment in each S22 should be 5%) LHS | D31: 0.05 | E31: -0.00068069083 | F31: 0.05 | G31: 0.05 | H31: 1e+30
B32: $C$42 | C32: (minimum investment in each S31 should be 5%) LHS | D32: 0.1 | E32: 0 | F32: 0.05 | G32: 0.05 | H32: 1e+30
... B37: $C$52 | C37: non negative constrain LHS | D37: 1 | E37: 0 | F37: 0 | G37: 1 | H37: 1e+30

Sheet Answer Report 1
A1: Microsoft Excel 16.95 Answer Report
A2: Worksheet: [BASKAR_GOKUL_S223638072_MIS775.xlsx]2.a. LP Modelling
A3: Report Created: 10/04/25 12:13:32 PM
A4: Result: Solver found a solution. All constraints and optimality conditions are satisfied.
A5: Solver Engine
B6: Engine: Simplex LP
B7: Solution Time: 178.421 Seconds.
B8: Iterations: 21 Subproblems: 0
A9: Solver Options
B10: Max Time Unlimited, Iterations Unlimited, Precision 0.000001
B11: Max Subproblems Unlimited, Max Integer Sols Unlimited, Integer Tolerance 1%
A14: Objective Cell (Max)
B15: Cell | C15: Name | D15: Original Value | E15: Final Value
B16: $C$16 | C16: Maxmize portfolio return (ASX.PME) | D16: 0.016699656 | E16: 0.016699656
A19: Variable Cells
B20: Cell | C20: Name | D20: Original Value | E20: Final Value | F20: Integer
B21: $C$11 | C21: Investment weights (ASX.PME) | D21: 0.1 | E21: 0.1 | F21: Contin
B22: $D$11 | C22: Investment weights (ASX:PGC) | D22: 0.05 | E22: 0.05 | F22: Contin
B23: $E$11 | C23: Investment weights (ASX:XRO) | D23: 0.1 | E23: 0.1 | F23: Contin
B24: $F$11 | C24: Investment weights (ASX:COS) | D24: 0.05 | E24: 0.05 | F24: Contin
B25: $G$11 | C25: Investment weights (ASX:TLS) | D25: 0.1 | E25: 0.1 | F25: Contin
B26: $H$11 | C26: Investment weights (ASX:TPG) | D26: 0.05 | E26: 0.05 | F26: Contin
B27: $I$11 | C27: Investment weights (ASX:CBA) | D27: 0.05 | E27: 0.05 | F27: Contin
B28: $J$11 | C28: Investment weights (ASX:SUN) | D28: 0.5 | E28: 0.5 | F28: Contin
A31: Constraints
B32: Cell | C32: Name | D32: Cell Value | E32: Formula | F32: Status | G32: Slack
B33: $C$20 | C33: (High Risk assets should be less Than 15%) LHS | D33: 0.15 | E33: $C$20<=$E$20 | F33: Binding | G33: 0
B34: $C$22 | C34: (Low risk stocks should be greater than Medium Risk stock(R2) LHS | D34: 0.65 | E34: $C$22>=$E$22 | F34: Not Binding | G34: 0.45
B35: $C$24 | C35: (Low Risk Stock Receive higest allocaton than R3. ) LHS | D35: 0.65 | E35: $C$24>=$E$24 | F35: Not Binding | G35: 0.5
B36: $C$26 | C36: (Health care sector must have a minimum of 15% invested) LHS | D36: 0.15 | E36: $C$26>=$E$26 | F36: Binding | G36: 0
B37: $C$28 | C37: (Technology sector must have a minimum of 15% invested) LHS | D37: 0.15 | E37: $C$28>=$E$28 | F37: Binding | G37: 0
B38: $C$30 | C38: (Communication Service sector must have a minimum of 15% invested) LHS | D38: 0.15 | E38: $C$30>=$E$30 | F38: Binding | G38: 0
B39: $C$32 | C39: (Finance sector must have a minimum of 20% invested) LHS | D39: 0.55 | E39: $C$32>=$E$32 | F39: Not Binding | G39: 0.35
B40: $C$34 | C40: (minimum investment in each S11 should be 5%) LHS | D40: 0.1 | E40: $C$34>=$E$34 | F40: Not Binding | G40: 0.05
B41: $C$36 | C41: (minimum investment in each S12 should be 5%) LHS | D41: 0.05 | E41: $C$36>=$E$36 | F41: Binding | G41: 0
B42: $C$38 | C42: (minimum investment in each S21 should be 5%) LHS | D42: 0.1 | E42: $C$38>=$E$38 | F42: Not Binding | G42: 0.05
B43: $C$40 | C43: (minimum investment in each S22 should be 5%) LHS | D43: 0.05 | E43: $C$40>=$E$40 | F43: Binding | G43: 0
B44: $C$42 | C44: (minimum investment in each S31 should be 5%) LHS | D44: 0.1 | E44: $C$42>=$E$42 | F44: Not Binding | G44: 0.05
... B49: $C$52 | C49: non negative constrain LHS | D49: 1 | E49: $C$52>=$E$52 | F49: Not Binding | G49: 1

Sheet 3a. ILP Modelling
B1: INTERGER LINEAR PROGRAMING
B3: INPUTS | C3: Healthcare | E3: Technology | G3: Communication Service | I3: Finance
C4: (ASX.PME) | D4: (ASX:PGC) | E4: (ASX:XRO) | F4: (ASX:COS) | G4: (ASX:TLS) | H4: (ASX:TPG) | I4: (ASX:CBA) | J4: (ASX:SUN)
B5: Stock | C5: S11 | D5: S12 | E5: S21 | F5: S22 | G5: S31 | H5: S32 | I5: S41 | J5: S42
B6: Mean | C6: 0.045530186 | D6: 0.025564443 | E6: 0.011564818 | F6: 0.010884127 | G6: 0.0055431375 | H6: -0.0082112647 | I6: 0.015632543 | J6: 0.016484699
A9: DECISION VARIABLES | C9: R3 (High Risk) | D9: R3 (High Risk) | E9: R2 (Medium Risk) | F9: R2 (Medium Risk) | G9: R1 (Low risk) | H9: R2 (Medium Risk) | I9: R1 (Low risk) | J9: R1 (Low risk)
C10: (ASX.PME) | D10: (ASX:PGC) | E10: (ASX:XRO) | F10: (ASX:COS) | G10: (ASX:TLS) | H10: (ASX:TPG) | I10: (ASX:CBA) | J10: (ASX:SUN)
B11: Investment weights | C11: 1 | D11: 0 | E11: 1 | F11: 0 | G11: 1 | H11: 0 | I11: 1 | J11: 1 | K11: Yes=1 NO=0
A16: OBJECTIVE FUNCTION
B18: Maximum portfolio return | C18: =SUMPRODUCT(C6:J6,C11:J11) -> 0.094755384
A20: CONSTRAINTS
A21: LHS | C21: RHS
A22: =SUM(C11:J11) -> 5 | B22: = | C22: 5 | E22: (5 Stocks needed to be Choosen )
A24: =SUM(C11:D11) -> 1 | B24: >= | C24: 1 | E24: (At least 1 in Health Sector)
A26: =SUM(E11:F11) -> 1 | B26: >= | C26: 1 | E26: (At lease 1 in Technology Sector)
A28: =SUM(G11:H11) -> 1 | B28: >= | C28: 1 | E28: (Atleast 1 in Communication Sector )
A30: =SUM(I11:J11) -> 2 | B30: >= | C30: 1 | E30: (Atleast 1 in Finacial Sector )
A32: =SUM(C11,D11,) -> 1 | B32: <= | C32: 1 | E32: (One Stock in the Riskiest Group (R3))
A34: =SUM(I11,G11,J11) -> 3 | B34: >= | C34: 2 | E34: (Two Stocks in the Least Risky Group R1)
A36: =SUM(C11,D11) -> 1 | B36: <= | C36: =SUM(E11,F11,H11) -> 1 | E36: (R3 Stock Selection Requires at Least One R2 Stock)

Sheet Summary Sheet
D2: LP Model summary sheet
C3: Symbol | D3: Company | E3: Sector code | F3: sub sector code for chosen assests | G3: Average 4 year return | H3: Stnd Deviation | I3: Risk Category (R1 / R2 /R3) | J3: Proportion of investment
C4: (ASX:PME) | D4: Pro Medicus Limited | E4: S1 | F4: S11 | G4: ='1.b Sample (Return and Risk)'!C56 -> 0.045530186 | H4: ='1.b Sample (Return and Risk)'!C57 -> 0.10936386 | I4: R3 (High Risk) | J4: ='2.a. LP Modelling'!C11 -> 0.1
C5: (ASX:PGC) | D5: Paragon Care Limited | F5: S12 | G5: ='1.b Sample (Return and Risk)'!D56 -> 0.025564443 | H5: ='1.b Sample (Return and Risk)'!D57 -> 0.13553167 | I5: R3 (High Risk) | J5: ='2.a. LP Modelling'!D11 -> 0.05
C6: (ASX:XRO) | D6: Xero Limited | E6: S2 | F6: S21 | G6: ='1.b Sample (Return and Risk)'!E56 -> 0.011564818 | H6: ='1.b Sample (Return and Risk)'!E57 -> 0.094151229 | I6: R2 (Medium Risk) | J6: ='2.a. LP Modelling'!E11 -> 0.1
C7: (ASX:COS) | D7: COSOL Limited | F7: S22 | G7: ='1.b Sample (Return and Risk)'!F56 -> 0.010884127 | H7: ='1.b Sample (Return and Risk)'!F57 -> 0.080188898 | I7: R2 (Medium Risk) | J7: ='2.a. LP Modelling'!F11 -> 0.05
C8: (ASX:TLS) | D8: Telstra Group Limited | E8: S3 | F8: S31 | G8: ='1.b Sample (Return and Risk)'!G56 -> 0.0055431375 | H8: ='1.b Sample (Return and Risk)'!G57 -> 0.035698466 | I8: R1 (Low risk) | J8: ='2.a. LP Modelling'!G11 -> 0.1
C9: (ASX:TPG) | D9: TPG Telecom Limited | F9: S32 | G9: ='1.b Sample (Return and Risk)'!H56 -> -0.0082112647 | H9: ='1.b Sample (Return and Risk)'!H57 -> 0.07254004 | I9: R2 (Medium Risk) | J9: ='2.a. LP Modelling'!H11 -> 0.05
C10: (ASX:CBA) | D10: Commonwealth Bank | E10: S4 | F10: S41 | G10: ='1.b Sample (Return and Risk)'!I56 -> 0.015632543 | H10: ='1.b Sample (Return and Risk)'!I57 -> 0.062967476 | I10: R1 (Low risk) | J10: ='2.a. LP Modelling'!I11 -> 0.05
C11: (ASX:SUN) | D11: Suncorp Group Limited | F11: S42 | G11: ='1.b Sample (Return and Risk)'!J56 -> 0.016484699 | H11: ='1.b Sample (Return and Risk)'!J57 -> 0.048592931 | I11: R1 (Low risk) | J11: ='2.a. LP Modelling'!J11 -> 0.5
D13: optimal Value | E13: ='2.a. LP Modelling'!C16 -> 0.016699656 | I13: Total Investment | J13: =SUM(J4:J11) -> 1
D17: ILP Model summary sheet
C18: Symbol | D18: Company | E18: Sector code | F18: sub sector code for chosen assests | G18: Average 4 year return | H18: Stnd Deviation | I18: Risk Category (R1 / R2 /R3) | J18: investment
C19: (ASX:PME) | D19: Pro Medicus Limited | E19: S1 | F19: S11 | G19: 0.045530186 | H19: 0.10936386 | I19: R3 (High Risk) | J19: ='3a. ILP Modelling'!C11 -> 1
C20: (ASX:PGC) | D20: Paragon Care Limited | F20: S12 | G20: 0.025564443 | H20: 0.13553167 | I20: R3 (High Risk) | J20: ='3a. ILP Modelling'!D11 -> 0
C21: (ASX:XRO) | D21: Xero Limited | E21: S2 | F21: S21 | G21: 0.011564818 | H21: 0.094151229 | I21: R2 (Medium Risk) | J21: ='3a. ILP Modelling'!E11 -> 1
C22: (ASX:COS) | D22: COSOL Limited | F22: S22 | G22: 0.010884127 | H22: 0.080188898 | I22: R2 (Medium Risk) | J22: ='3a. ILP Modelling'!F11 -> 0
C23: (ASX:TLS) | D23: Telstra Group Limited | E23: S3 | F23: S31 | G23: 0.0055431375 | H23: 0.035698466 | I23: R1 (Low risk) | J23: ='3a. ILP Modelling'!G11 -> 1
C24: (ASX:TPG) | D24: TPG Telecom Limited | F24: S32 | G24: -0.0082112647 | H24: 0.07254004 | I24: R2 (Medium Risk) | J24: ='3a. ILP Modelling'!H11 -> 0
C25: (ASX:CBA) | D25: Commonwealth Bank | E25: S4 | F25: S41 | G25: 0.015632543 | H25: 0.062967476 | I25: R1 (Low risk) | J25: ='3a. ILP Modelling'!I11 -> 1
C26: (ASX:SUN) | D26: Suncorp Group Limited | F26: S42 | G26: 0.016484699 | H26: 0.048592931 | I26: R1 (Low risk) | J26: ='3a. ILP Modelling'!J11 -> 1
D28: optimal Value | E28: ='3a. ILP Modelling'!C18 -> 0.094755384 | I28: Total Investment | J28: =SUM(J19:J26) -> 5
